Workbook

Sheet Legend
A1: Wind + BESS 115 kV Interconnection — Calculation Workbook
A2: PRELIMINARY ENGINEERING — NOT FOR CONSTRUCTION | Rev P0 | 2026-10-13
A4: Purpose | B4: Traceable formulas supporting the preliminary engineering report (Appendix A).
A5: Blue text | B5: Hard-coded inputs (edit only on sheet "Inputs").
A6: Black text | B6: Formulas — do not overwrite.
A7: Yellow fill | B7: Engineering assumption / parametric value requiring OEM, site or utility confirmation.
A8: Green fill | B8: Frozen project data supplied by the client.
A9: Flags | B9: F = frozen project data | A = engineering assumption | P = parametric/illustrative | O = OEM to confirm | U = utility to confirm
A10: Independent check | B10: Sheet "Check" compares each key workbook result with the separate Python engine (calc.py). |Δ| must be < 0.5 %.
A11: Status | B11: No site cable lengths, soil thermal data, utility fault levels, OEM impedances or PCS data were available. Values depending on these are screening values only.

Sheet Inputs
A1: Inputs
A2: PRELIMINARY ENGINEERING — NOT FOR CONSTRUCTION | Rev P0 | 2026-10-13
A4: Parameter | B4: Symbol | C4: Value | D4: Unit | E4: Flag | F4: Basis / source
A5: Number of WTGs | B5: N_WTG | C5: 27 | D5: - | E5: F | F5: Client frozen data
A6: WTG rated active power | B6: P_WTG | C6: 3.8 | D6: MW | E6: F | F6: Client frozen data (GE Vernova DFIG; model TBC by OEM)
A7: WTG reactive capability at rated P (PF) | B7: PF_WTG | C7: 0.95 | D7: - | E7: A/O | F7: Screening for kVA/current sizing; confirm GE Vernova P-Q capability chart
A8: WTG LV voltage | B8: V_LV | C8: 0.69 | D8: kV | E8: F | F8: Client frozen data
A9: Collector voltage | B9: V_MV | C9: 34.5 | D9: kV | E9: F | F9: Client frozen data
A10: POI voltage | B10: V_HV | C10: 115 | D10: kV | E10: F | F10: Client frozen data
A11: Minimum steady-state voltage for current sizing | B11: V_MIN | C11: 0.95 | D11: pu | E11: A | F11: Screening; confirm with load-flow and SoCo voltage schedule
A12: WTGs on WF-01 | B12: N_F1 | C12: 7 | D12: - | E12: F | F12: Client
A13: WTGs on WF-02 | B13: N_F2 | C13: 7 | D13: - | E13: F | F13: Client
A14: WTGs on WF-03 | B14: N_F3 | C14: 7 | D14: - | E14: F | F14: Client
A15: WTGs on WF-04 | B15: N_F4 | C15: 6 | D15: - | E15: F | F15: Client
A16: POI export limit | B16: P_EXP | C16: 100 | D16: MW | E16: F | F16: Client
... A53: Auxiliary/station load | B53: AUX | C53: 1 | D53: MW | E53: A | F53: Placeholder pending aux load list (incl. BESS HVAC)

Sheet WTG
A1: WTG electrical quantities and step-up transformer kVA
A2: PRELIMINARY ENGINEERING — NOT FOR CONSTRUCTION | Rev P0 | 2026-10-13
A4: Quantity | B4: Equation | C4: Value | D4: Unit
A5: Apparent power S_WTG | B5: S = P / PF | C5: =P_WTG/PF_WTG -> 4 | D5: MVA
A6: Reactive power Q_WTG | B6: Q = √(S²−P²) | C6: =SQRT(C5^2-P_WTG^2) -> 1.2489996 | D6: Mvar
A7: LV current, unity PF | B7: I = P/(√3·V) | C7: =P_WTG*1000000/(SQRT(3)*V_LV*1000) -> 3179.6102 | D7: A
A8: LV current at S_WTG | B8: I = S/(√3·V) | C8: =C5*1000000/(SQRT(3)*V_LV*1000) -> 3346.9581 | D8: A
A9: LV current at S_WTG, V_MIN | B9: I = S/(√3·V·Vpu) | C9: =C8/V_MIN -> 3523.1138 | D9: A
A10: MV current, unity PF | B10: I = P/(√3·34.5 kV) | C10: =P_WTG*1000000/(SQRT(3)*V_MV*1000) -> 63.592204 | D10: A
A11: MV current at S_WTG | C11: =C5*1000000/(SQRT(3)*V_MV*1000) -> 66.939162 | D11: A
A12: MV current at S_WTG, V_MIN | C12: =C11/V_MIN -> 70.462275 | D12: A
A13: Minimum WTG transformer rating | B13: S_T ≥ S_WTG (+aux, harmonics per OEM) | C13: =C5 -> 4 | D13: MVA
A14: Gross wind P | B14: ΣP | C14: =N_WTG*P_WTG -> 102.6 | D14: MW
A15: Gross wind S | B15: ΣS | C15: =N_WTG*C5 -> 108 | D15: MVA
A16: Gross wind MV current | C16: =C15*1000000/(SQRT(3)*V_MV*1000) -> 1807.3574 | D16: A

Sheet Cable_Ampacity
A1: Cable parameters & IEC 60287 steady-state ampacity — 35 kV Al, 3×1C trefoil touching, direct buried, solidly bonded
A2: PRELIMINARY ENGINEERING — NOT FOR CONSTRUCTION | Rev P0 | 2026-10-13
A4: Size | B4: A (mm²) | C4: dc (mm) | D4: R20 (Ω/m) | E4: R'90 (Ω/m) | F4: xs⁴ | G4: ys | H4: xp⁴ | I4: dc/s | J4: yp | K4: Rac90 (Ω/m) | L4: Di (mm) | M4: dS (mm) | N4: Da (mm) | O4: De (mm) | P4: C (F/m) | Q4: Wd (W/m) | R4: As (mm²) | S4: Rs (Ω/m) | T4: Xs (Ω/m) | U4: λ1 | V4: T1 | W4: T3 | X4: u | Y4: T4 | Z4: Ampacity (A) | AA4: X (Ω/m) | AB4: Qc (kvar/km) | AC4: Rac (Ω/km) | AD4: X (Ω/km) | AE4: T4 grouped | AF4: Ampacity grouped (A)
A5: 1/0 AWG | B5: 53.49 | C5: 8.53 | D5: =RHO_AL*K_STR/(B5*0.000001) -> 0.00053896579 | E5: =D5*(1+ALPHA_AL*(T_MAX-20)) -> 0.00069100804 | F5: =(8*PI()*FREQ/E5*0.0000001)^2 -> 0.04762292 | G5: =F5/(192+0.8*F5) -> 0.00024798684 | H5: =(8*PI()*FREQ/E5*0.0000001*0.8)^2 -> 0.030478669 | I5: =C5/O5 -> 0.20685809 | J5: =H5/(192+0.8*H5)*I5^2*(0.312*I5^2+1.18/(H5/(192+0.8*H5)+0.27)) -> 2.9755898e-05 | K5: =E5*(1+G5+J5) -> 0.00069119996 | L5: =C5+2*T_CS+2*T_INS -> 31.07 | M5: =L5+2*T_IS+D_W -> 35.123 | N5: =L5+2*T_IS+2*D_W -> 37.176 | O5: =N5+2*T_J -> 41.236 | P5: =EPS/(18*LN(L5/(C5+2*T_CS)))*0.000000001 -> 1.196257e-10 | Q5: =2*PI()*FREQ*P5*(V_MV*1000/SQRT(3))^2*TAND -> 0.071570252 | R5: =N_W*PI()*D_W^2/4 -> 36.413336 | S5: =0.000000017241*(1+0.00393*(T_SCR-20))/(R5*0.000001) -> 0.00058512705 | T5: =2*2*PI()*FREQ*0.0000001*LN(2*O5/M5) -> 6.4360124e-05 | U5: =S5/K5/(1+(S5/T5)^2) -> 0.010119453 | V5: =RHO_I/(2*PI())*LN(1+2*(T_CS+T_INS+T_IS)/C5) -> 0.75481302 | W5: =RHO_J/(2*PI())*LN(1+2*T_J/N5) -> 0.05773647 | X5: =2*DEPTH/(O5/1000) -> 48.50131 | Y5: =1.5/PI()*RHO_S*(LN(2*X5)-0.63) -> 2.2601684 | Z5: =SQRT(((T_MAX-T_AMB)-Q5*(0.5*V5+W5+Y5))/(K5*V5+K5*(1+U5)*(W5+Y5))) -> 174.01904 | AA5: =2*PI()*FREQ*0.0000002*LN(O5/(0.7788*C5/2)) -> 0.00018991836 | AB5: =(V_MV*1000)^2*2*PI()*FREQ*P5 -> 53.677689 | AC5: =K5*1000 -> 0.69119996 | AD5: =AA5*1000 -> 0.18991836 | AE5: =Y5+RHO_S*3/(2*PI())*(2*LN(SQRT(GSP^2+(2*DEPTH)^2)/GSP)+LN(SQRT((2*GSP)^2+(2*DEPTH)^2)/(2*GSP))) -> 2.7212384 | AF5: =SQRT(((T_MAX-T_AMB)-Q5*(0.5*V5+W5+AE5))/(K5*V5+K5*(1+U5)*(W5+AE5))) -> 162.20244
A6: 4/0 AWG | B6: 107.2 | C6: 12.07 | D6: =RHO_AL*K_STR/(B6*0.000001) -> 0.00026892985 | E6: =D6*(1+ALPHA_AL*(T_MAX-20)) -> 0.00034479496 | F6: =(8*PI()*FREQ/E6*0.0000001)^2 -> 0.19127596 | G6: =F6/(192+0.8*F6) -> 0.00099543563 | H6: =(8*PI()*FREQ/E6*0.0000001*0.8)^2 -> 0.12241662 | I6: =C6/O6 -> 0.26956405 | J6: =H6/(192+0.8*H6)*I6^2*(0.312*I6^2+1.18/(H6/(192+0.8*H6)+0.27)) -> 0.00020294971 | K6: =E6*(1+G6+J6) -> 0.00034520816 | L6: =C6+2*T_CS+2*T_INS -> 34.61 | M6: =L6+2*T_IS+D_W -> 38.663 | N6: =L6+2*T_IS+2*D_W -> 40.716 | O6: =N6+2*T_J -> 44.776 | P6: =EPS/(18*LN(L6/(C6+2*T_CS)))*0.000000001 -> 1.4488166e-10 | Q6: =2*PI()*FREQ*P6*(V_MV*1000/SQRT(3))^2*TAND -> 0.086680508 | R6: =N_W*PI()*D_W^2/4 -> 36.413336 | S6: =0.000000017241*(1+0.00393*(T_SCR-20))/(R6*0.000001) -> 0.00058512705 | T6: =2*2*PI()*FREQ*0.0000001*LN(2*O6/M6) -> 6.3329712e-05 | U6: =S6/K6/(1+(S6/T6)^2) -> 0.019625735 | V6: =RHO_I/(2*PI())*LN(1+2*(T_CS+T_INS+T_IS)/C6) -> 0.61809324 | W6: =RHO_J/(2*PI())*LN(1+2*T_J/N6) -> 0.052947509 | X6: =2*DEPTH/(O6/1000) -> 44.666786 | Y6: =1.5/PI()*RHO_S*(LN(2*X6)-0.63) -> 2.2129792 | Z6: =SQRT(((T_MAX-T_AMB)-Q6*(0.5*V6+W6+Y6))/(K6*V6+K6*(1+U6)*(W6+Y6))) -> 253.13215 | AA6: =2*PI()*FREQ*0.0000002*LN(O6/(0.7788*C6/2)) -> 0.00016995494 | AB6: =(V_MV*1000)^2*2*PI()*FREQ*P6 -> 65.010381 | AC6: =K6*1000 -> 0.34520816 | AD6: =AA6*1000 -> 0.16995494 | AE6: =Y6+RHO_S*3/(2*PI())*(2*LN(SQRT(GSP^2+(2*DEPTH)^2)/GSP)+LN(SQRT((2*GSP)^2+(2*DEPTH)^2)/(2*GSP))) -> 2.6740492 | AF6: =SQRT(((T_MAX-T_AMB)-Q6*(0.5*V6+W6+AE6))/(K6*V6+K6*(1+U6)*(W6+AE6))) -> 234.90085
A7: 350 kcmil | B7: 177.3 | C7: 15.65 | D7: =RHO_AL*K_STR/(B7*0.000001) -> 0.00016260169 | E7: =D7*(1+ALPHA_AL*(T_MAX-20)) -> 0.00020847163 | F7: =(8*PI()*FREQ/E7*0.0000001)^2 -> 0.52322477 | G7: =F7/(192+0.8*F7) -> 0.0027192009 | H7: =(8*PI()*FREQ/E7*0.0000001*0.8)^2 -> 0.33486385 | I7: =C7/O7 -> 0.32364133 | J7: =H7/(192+0.8*H7)*I7^2*(0.312*I7^2+1.18/(H7/(192+0.8*H7)+0.27)) -> 0.000798126 | K7: =E7*(1+G7+J7) -> 0.00020920489 | L7: =C7+2*T_CS+2*T_INS -> 38.19 | M7: =L7+2*T_IS+D_W -> 42.243 | N7: =L7+2*T_IS+2*D_W -> 44.296 | O7: =N7+2*T_J -> 48.356 | P7: =EPS/(18*LN(L7/(C7+2*T_CS)))*0.000000001 -> 1.6974453e-10 | Q7: =2*PI()*FREQ*P7*(V_MV*1000/SQRT(3))^2*TAND -> 0.10155559 | R7: =N_W*PI()*D_W^2/4 -> 36.413336 | S7: =0.000000017241*(1+0.00393*(T_SCR-20))/(R7*0.000001) -> 0.00058512705 | T7: =2*2*PI()*FREQ*0.0000001*LN(2*O7/M7) -> 6.245226e-05 | U7: =S7/K7/(1+(S7/T7)^2) -> 0.031503212 | V7: =RHO_I/(2*PI())*LN(1+2*(T_CS+T_INS+T_IS)/C7) -> 0.52537294 | W7: =RHO_J/(2*PI())*LN(1+2*T_J/N7) -> 0.048850343 | X7: =2*DEPTH/(O7/1000) -> 41.359914 | Y7: =1.5/PI()*RHO_S*(LN(2*X7)-0.63) -> 2.1689084 | Z7: =SQRT(((T_MAX-T_AMB)-Q7*(0.5*V7+W7+Y7))/(K7*V7+K7*(1+U7)*(W7+Y7))) -> 331.698 | AA7: =2*PI()*FREQ*0.0000002*LN(O7/(0.7788*C7/2)) -> 0.0001561699 | AB7: =(V_MV*1000)^2*2*PI()*FREQ*P7 -> 76.166694 | AC7: =K7*1000 -> 0.20920489 | AD7: =AA7*1000 -> 0.1561699 | AE7: =Y7+RHO_S*3/(2*PI())*(2*LN(SQRT(GSP^2+(2*DEPTH)^2)/GSP)+LN(SQRT((2*GSP)^2+(2*DEPTH)^2)/(2*GSP))) -> 2.6299784 | AF7: =SQRT(((T_MAX-T_AMB)-Q7*(0.5*V7+W7+AE7))/(K7*V7+K7*(1+U7)*(W7+AE7))) -> 306.66584
A8: 500 kcmil | B8: 253.4 | C8: 18.69 | D8: =RHO_AL*K_STR/(B8*0.000001) -> 0.00011376985 | E8: =D8*(1+ALPHA_AL*(T_MAX-20)) -> 0.00014586432 | F8: =(8*PI()*FREQ/E8*0.0000001)^2 -> 1.0687695 | G8: =F8/(192+0.8*F8) -> 0.0055418289 | H8: =(8*PI()*FREQ/E8*0.0000001*0.8)^2 -> 0.68401248 | I8: =C8/O8 -> 0.36364698 | J8: =H8/(192+0.8*H8)*I8^2*(0.312*I8^2+1.18/(H8/(192+0.8*H8)+0.27)) -> 0.0020457961 | K8: =E8*(1+G8+J8) -> 0.00014697109 | L8: =C8+2*T_CS+2*T_INS -> 41.23 | M8: =L8+2*T_IS+D_W -> 45.283 | N8: =L8+2*T_IS+2*D_W -> 47.336 | O8: =N8+2*T_J -> 51.396 | P8: =EPS/(18*LN(L8/(C8+2*T_CS)))*0.000000001 -> 1.9053305e-10 | Q8: =2*PI()*FREQ*P8*(V_MV*1000/SQRT(3))^2*TAND -> 0.11399305 | R8: =N_W*PI()*D_W^2/4 -> 36.413336 | S8: =0.000000017241*(1+0.00393*(T_SCR-20))/(R8*0.000001) -> 0.00058512705 | T8: =2*2*PI()*FREQ*0.0000001*LN(2*O8/M8) -> 6.1809642e-05 | U8: =S8/K8/(1+(S8/T8)^2) -> 0.043935044 | V8: =RHO_I/(2*PI())*LN(1+2*(T_CS+T_INS+T_IS)/C8) -> 0.46710564 | W8: =RHO_J/(2*PI())*LN(1+2*T_J/N8) -> 0.045838589 | X8: =2*DEPTH/(O8/1000) -> 38.913534 | Y8: =1.5/PI()*RHO_S*(LN(2*X8)-0.63) -> 2.1339752 | Z8: =SQRT(((T_MAX-T_AMB)-Q8*(0.5*V8+W8+Y8))/(K8*V8+K8*(1+U8)*(W8+Y8))) -> 400.71111 | AA8: =2*PI()*FREQ*0.0000002*LN(O8/(0.7788*C8/2)) -> 0.00014738241 | AB8: =(V_MV*1000)^2*2*PI()*FREQ*P8 -> 85.494787 | AC8: =K8*1000 -> 0.14697109 | AD8: =AA8*1000 -> 0.14738241 | AE8: =Y8+RHO_S*3/(2*PI())*(2*LN(SQRT(GSP^2+(2*DEPTH)^2)/GSP)+LN(SQRT((2*GSP)^2+(2*DEPTH)^2)/(2*GSP))) -> 2.5950452 | AF8: =SQRT(((T_MAX-T_AMB)-Q8*(0.5*V8+W8+AE8))/(K8*V8+K8*(1+U8)*(W8+AE8))) -> 369.44064
A9: 750 kcmil | B9: 380 | C9: 23.06 | D9: =RHO_AL*K_STR/(B9*0.000001) -> 7.5866526e-05 | E9: =D9*(1+ALPHA_AL*(T_MAX-20)) -> 9.7268473e-05 | F9: =(8*PI()*FREQ/E9*0.0000001)^2 -> 2.4034662 | G9: =F9/(192+0.8*F9) -> 0.012393935 | H9: =(8*PI()*FREQ/E9*0.0000001*0.8)^2 -> 1.5382184 | I9: =C9/O9 -> 0.41351361 | J9: =H9/(192+0.8*H9)*I9^2*(0.312*I9^2+1.18/(H9/(192+0.8*H9)+0.27)) -> 0.0058511934 | K9: =E9*(1+G9+J9) -> 9.9043149e-05 | L9: =C9+2*T_CS+2*T_INS -> 45.6 | M9: =L9+2*T_IS+D_W -> 49.653 | N9: =L9+2*T_IS+2*D_W -> 51.706 | O9: =N9+2*T_J -> 55.766 | P9: =EPS/(18*LN(L9/(C9+2*T_CS)))*0.000000001 -> 2.2008169e-10 | Q9: =2*PI()*FREQ*P9*(V_MV*1000/SQRT(3))^2*TAND -> 0.13167155 | R9: =N_W*PI()*D_W^2/4 -> 36.413336 | S9: =0.000000017241*(1+0.00393*(T_SCR-20))/(R9*0.000001) -> 0.00058512705 | T9: =2*2*PI()*FREQ*0.0000001*LN(2*O9/M9) -> 6.1016219e-05 | U9: =S9/K9/(1+(S9/T9)^2) -> 0.063550493 | V9: =RHO_I/(2*PI())*LN(1+2*(T_CS+T_INS+T_IS)/C9) -> 0.40370708 | W9: =RHO_J/(2*PI())*LN(1+2*T_J/N9) -> 0.042107126 | X9: =2*DEPTH/(O9/1000) -> 35.864147 | Y9: =1.5/PI()*RHO_S*(LN(2*X9)-0.63) -> 2.0872195 | Z9: =SQRT(((T_MAX-T_AMB)-Q9*(0.5*V9+W9+Y9))/(K9*V9+K9*(1+U9)*(W9+Y9))) -> 494.76038 | AA9: =2*PI()*FREQ*0.0000002*LN(O9/(0.7788*C9/2)) -> 0.00013769322 | AB9: =(V_MV*1000)^2*2*PI()*FREQ*P9 -> 98.753663 | AC9: =K9*1000 -> 0.099043149 | AD9: =AA9*1000 -> 0.13769322 | AE9: =Y9+RHO_S*3/(2*PI())*(2*LN(SQRT(GSP^2+(2*DEPTH)^2)/GSP)+LN(SQRT((2*GSP)^2+(2*DEPTH)^2)/(2*GSP))) -> 2.5482895 | AF9: =SQRT(((T_MAX-T_AMB)-Q9*(0.5*V9+W9+AE9))/(K9*V9+K9*(1+U9)*(W9+AE9))) -> 454.52401
A10: 1000 kcmil | B10: 506.7 | C10: 26.92 | D10: =RHO_AL*K_STR/(B10*0.000001) -> 5.6896152e-05 | E10: =D10*(1+ALPHA_AL*(T_MAX-20)) -> 7.2946556e-05 | F10: =(8*PI()*FREQ/E10*0.0000001)^2 -> 4.273391 | G10: =F10/(192+0.8*F10) -> 0.02186787 | H10: =(8*PI()*FREQ/E10*0.0000001*0.8)^2 -> 2.7349703 | I10: =C10/O10 -> 0.4514809 | J10: =H10/(192+0.8*H10)*I10^2*(0.312*I10^2+1.18/(H10/(192+0.8*H10)+0.27)) -> 0.012107182 | K10: =E10*(1+G10+J10) -> 7.5424919e-05 | L10: =C10+2*T_CS+2*T_INS -> 49.46 | M10: =L10+2*T_IS+D_W -> 53.513 | N10: =L10+2*T_IS+2*D_W -> 55.566 | O10: =N10+2*T_J -> 59.626 | P10: =EPS/(18*LN(L10/(C10+2*T_CS)))*0.000000001 -> 2.4595896e-10 | Q10: =2*PI()*FREQ*P10*(V_MV*1000/SQRT(3))^2*TAND -> 0.14715353 | R10: =N_W*PI()*D_W^2/4 -> 36.413336 | S10: =0.000000017241*(1+0.00393*(T_SCR-20))/(R10*0.000001) -> 0.00058512705 | T10: =2*2*PI()*FREQ*0.0000001*LN(2*O10/M10) -> 6.0417674e-05 | U10: =S10/K10/(1+(S10/T10)^2) -> 0.081838404 | V10: =RHO_I/(2*PI())*LN(1+2*(T_CS+T_INS+T_IS)/C10) -> 0.36092737 | W10: =RHO_J/(2*PI())*LN(1+2*T_J/N10) -> 0.039282744 | X10: =2*DEPTH/(O10/1000) -> 33.542414 | Y10: =1.5/PI()*RHO_S*(LN(2*X10)-0.63) -> 2.048873 | Z10: =SQRT(((T_MAX-T_AMB)-Q10*(0.5*V10+W10+Y10))/(K10*V10+K10*(1+U10)*(W10+Y10))) -> 572.04817 | AA10: =2*PI()*FREQ*0.0000002*LN(O10/(0.7788*C10/2)) -> 0.00013107004 | AB10: =(V_MV*1000)^2*2*PI()*FREQ*P10 -> 110.36515 | AC10: =K10*1000 -> 0.075424919 | AD10: =AA10*1000 -> 0.13107004 | AE10: =Y10+RHO_S*3/(2*PI())*(2*LN(SQRT(GSP^2+(2*DEPTH)^2)/GSP)+LN(SQRT((2*GSP)^2+(2*DEPTH)^2)/(2*GSP))) -> 2.509943 | AF10: =SQRT(((T_MAX-T_AMB)-Q10*(0.5*V10+W10+AE10))/(K10*V10+K10*(1+U10)*(W10+AE10))) -> 524.03581
A11: 1250 kcmil | B11: 633.4 | C11: 30.23 | D11: =RHO_AL*K_STR/(B11*0.000001) -> 4.5515125e-05 | E11: =D11*(1+ALPHA_AL*(T_MAX-20)) -> 5.8354941e-05 | F11: =(8*PI()*FREQ/E11*0.0000001)^2 -> 6.6777006 | G11: =F11/(192+0.8*F11) -> 0.033838186 | H11: =(8*PI()*FREQ/E11*0.0000001*0.8)^2 -> 4.2737284 | I11: =C11/O11 -> 0.48032922 | J11: =H11/(192+0.8*H11)*I11^2*(0.312*I11^2+1.18/(H11/(192+0.8*H11)+0.27)) -> 0.020762322 | K11: =E11*(1+G11+J11) -> 6.1541151e-05 | L11: =C11+2*T_CS+2*T_INS -> 52.77 | M11: =L11+2*T_IS+D_W -> 56.823 | N11: =L11+2*T_IS+2*D_W -> 58.876 | O11: =N11+2*T_J -> 62.936 | P11: =EPS/(18*LN(L11/(C11+2*T_CS)))*0.000000001 -> 2.6803213e-10 | Q11: =2*PI()*FREQ*P11*(V_MV*1000/SQRT(3))^2*TAND -> 0.16035958 | R11: =N_W*PI()*D_W^2/4 -> 36.413336 | S11: =0.000000017241*(1+0.00393*(T_SCR-20))/(R11*0.000001) -> 0.00058512705 | T11: =2*2*PI()*FREQ*0.0000001*LN(2*O11/M11) -> 5.9966043e-05 | U11: =S11/K11/(1+(S11/T11)^2) -> 0.098822859 | V11: =RHO_I/(2*PI())*LN(1+2*(T_CS+T_INS+T_IS)/C11) -> 0.33105458 | W11: =RHO_J/(2*PI())*LN(1+2*T_J/N11) -> 0.037146254 | X11: =2*DEPTH/(O11/1000) -> 31.778314 | Y11: =1.5/PI()*RHO_S*(LN(2*X11)-0.63) -> 2.017918 | Z11: =SQRT(((T_MAX-T_AMB)-Q11*(0.5*V11+W11+Y11))/(K11*V11+K11*(1+U11)*(W11+Y11))) -> 636.93876 | AA11: =2*PI()*FREQ*0.0000002*LN(O11/(0.7788*C11/2)) -> 0.00012639997 | AB11: =(V_MV*1000)^2*2*PI()*FREQ*P11 -> 120.26968 | AC11: =K11*1000 -> 0.061541151 | AD11: =AA11*1000 -> 0.12639997 | AE11: =Y11+RHO_S*3/(2*PI())*(2*LN(SQRT(GSP^2+(2*DEPTH)^2)/GSP)+LN(SQRT((2*GSP)^2+(2*DEPTH)^2)/(2*GSP))) -> 2.478988 | AF11: =SQRT(((T_MAX-T_AMB)-Q11*(0.5*V11+W11+AE11))/(K11*V11+K11*(1+U11)*(W11+AE11))) -> 582.16113
A13: Notes
A14: Method: IEC 60287-1-1 (losses) and IEC 60287-2-1 (thermal resistances, T4 for equally loaded trefoil touching: T4 = 1.5/π·ρ·[ln(2u) − 0.630]).
A15: 100 % load factor assumed (conservative). Wind cyclic rating per IEC 60853 / Neher-McGrath with site LF may justify higher ratings — to be done in CYMCAP/ETAP.
A16: λ1 = circulating-current loss factor for solidly bonded concentric neutrals; eddy losses neglected for wire screens.
A17: Results are SCREENING ONLY: soil thermal resistivity, ambient, depth and duct-bank/crossing hot-spots are not yet known.

Sheet Feeder_Sections
A1: Collector feeder cumulative section currents, minimum conductor size, illustrative voltage drop & losses
A2: PRELIMINARY ENGINEERING — NOT FOR CONSTRUCTION | Rev P0 | 2026-10-13
A4: Feeder | B4: Section # | C4: From node | D4: WTGs carried k | E4: P (MW) | F4: S (MVA) | G4: I @1.0 pu (A) | H4: I @V_MIN (A) | I4: Min. size (ampacity ≥ I@V_MIN; home-run: grouped) | J4: Ampacity (A) | K4: Loading % | L4: Illustr. L (km) | M4: Rac (Ω/km) | N4: X (Ω/km) | O4: ΔV (%) | P4: Loss (kW)
A5: WF-01 | B5: 1 | C5: WF-01-T07 → WF-01-T06 | D5: 1 | E5: =D5*P_WTG -> 3.8 | F5: =D5*WTG!$C$5 -> 4 | G5: =F5*1000000/(SQRT(3)*V_MV*1000) -> 66.939162 | H5: =G5/V_MIN -> 70.462275 | I5: =INDEX(SIZE_LIST,IFERROR(MATCH(H5-0.0001,AMP_LIST,1),0)+1) -> 1/0 AWG | J5: =INDEX(AMP_LIST,MATCH(I5,SIZE_LIST,0)) -> 174.01904 | K5: =H5/J5 -> 0.4049113 | L5: =L_INT -> 0.616 | M5: =INDEX(RAC_LIST,MATCH(I5,SIZE_LIST,0)) -> 0.69119996 | N5: =INDEX(X_LIST,MATCH(I5,SIZE_LIST,0)) -> 0.18991836 | O5: =SQRT(3)*G5*L5*(M5*PF_WTG+N5*SQRT(1-PF_WTG^2))/(V_MV*1000) -> 0.0014821096 | P5: =3*G5^2*M5*L5/1000 -> 5.7235596
A6: WF-01 | B6: 2 | C6: WF-01-T06 → WF-01-T05 | D6: 2 | E6: =D6*P_WTG -> 7.6 | F6: =D6*WTG!$C$5 -> 8 | G6: =F6*1000000/(SQRT(3)*V_MV*1000) -> 133.87832 | H6: =G6/V_MIN -> 140.92455 | I6: =INDEX(SIZE_LIST,IFERROR(MATCH(H6-0.0001,AMP_LIST,1),0)+1) -> 1/0 AWG | J6: =INDEX(AMP_LIST,MATCH(I6,SIZE_LIST,0)) -> 174.01904 | K6: =H6/J6 -> 0.80982261 | L6: =L_INT -> 0.616 | M6: =INDEX(RAC_LIST,MATCH(I6,SIZE_LIST,0)) -> 0.69119996 | N6: =INDEX(X_LIST,MATCH(I6,SIZE_LIST,0)) -> 0.18991836 | O6: =SQRT(3)*G6*L6*(M6*PF_WTG+N6*SQRT(1-PF_WTG^2))/(V_MV*1000) -> 0.0029642192 | P6: =3*G6^2*M6*L6/1000 -> 22.894238
A7: WF-01 | B7: 3 | C7: WF-01-T05 → WF-01-T04 | D7: 3 | E7: =D7*P_WTG -> 11.4 | F7: =D7*WTG!$C$5 -> 12 | G7: =F7*1000000/(SQRT(3)*V_MV*1000) -> 200.81748 | H7: =G7/V_MIN -> 211.38683 | I7: =INDEX(SIZE_LIST,IFERROR(MATCH(H7-0.0001,AMP_LIST,1),0)+1) -> 4/0 AWG | J7: =INDEX(AMP_LIST,MATCH(I7,SIZE_LIST,0)) -> 253.13215 | K7: =H7/J7 -> 0.83508485 | L7: =L_INT -> 0.616 | M7: =INDEX(RAC_LIST,MATCH(I7,SIZE_LIST,0)) -> 0.34520816 | N7: =INDEX(X_LIST,MATCH(I7,SIZE_LIST,0)) -> 0.16995494 | O7: =SQRT(3)*G7*L7*(M7*PF_WTG+N7*SQRT(1-PF_WTG^2))/(V_MV*1000) -> 0.0023662856 | P7: =3*G7^2*M7*L7/1000 -> 25.726817
A8: WF-01 | B8: 4 | C8: WF-01-T04 → WF-01-T03 | D8: 4 | E8: =D8*P_WTG -> 15.2 | F8: =D8*WTG!$C$5 -> 16 | G8: =F8*1000000/(SQRT(3)*V_MV*1000) -> 267.75665 | H8: =G8/V_MIN -> 281.8491 | I8: =INDEX(SIZE_LIST,IFERROR(MATCH(H8-0.0001,AMP_LIST,1),0)+1) -> 350 kcmil | J8: =INDEX(AMP_LIST,MATCH(I8,SIZE_LIST,0)) -> 331.698 | K8: =H8/J8 -> 0.84971601 | L8: =L_INT -> 0.616 | M8: =INDEX(RAC_LIST,MATCH(I8,SIZE_LIST,0)) -> 0.20920489 | N8: =INDEX(X_LIST,MATCH(I8,SIZE_LIST,0)) -> 0.1561699 | O8: =SQRT(3)*G8*L8*(M8*PF_WTG+N8*SQRT(1-PF_WTG^2))/(V_MV*1000) -> 0.0020495237 | P8: =3*G8^2*M8*L8/1000 -> 27.717517
A9: WF-01 | B9: 5 | C9: WF-01-T03 → WF-01-T02 | D9: 5 | E9: =D9*P_WTG -> 19 | F9: =D9*WTG!$C$5 -> 20 | G9: =F9*1000000/(SQRT(3)*V_MV*1000) -> 334.69581 | H9: =G9/V_MIN -> 352.31138 | I9: =INDEX(SIZE_LIST,IFERROR(MATCH(H9-0.0001,AMP_LIST,1),0)+1) -> 500 kcmil | J9: =INDEX(AMP_LIST,MATCH(I9,SIZE_LIST,0)) -> 400.71111 | K9: =H9/J9 -> 0.87921539 | L9: =L_INT -> 0.616 | M9: =INDEX(RAC_LIST,MATCH(I9,SIZE_LIST,0)) -> 0.14697109 | N9: =INDEX(X_LIST,MATCH(I9,SIZE_LIST,0)) -> 0.14738241 | O9: =SQRT(3)*G9*L9*(M9*PF_WTG+N9*SQRT(1-PF_WTG^2))/(V_MV*1000) -> 0.001921544 | P9: =3*G9^2*M9*L9/1000 -> 30.425269
A10: WF-01 | B10: 6 | C10: WF-01-T02 → WF-01-T01 | D10: 6 | E10: =D10*P_WTG -> 22.8 | F10: =D10*WTG!$C$5 -> 24 | G10: =F10*1000000/(SQRT(3)*V_MV*1000) -> 401.63497 | H10: =G10/V_MIN -> 422.77365 | I10: =INDEX(SIZE_LIST,IFERROR(MATCH(H10-0.0001,AMP_LIST,1),0)+1) -> 750 kcmil | J10: =INDEX(AMP_LIST,MATCH(I10,SIZE_LIST,0)) -> 494.76038 | K10: =H10/J10 -> 0.85450184 | L10: =L_INT -> 0.616 | M10: =INDEX(RAC_LIST,MATCH(I10,SIZE_LIST,0)) -> 0.099043149 | N10: =INDEX(X_LIST,MATCH(I10,SIZE_LIST,0)) -> 0.13769322 | O10: =SQRT(3)*G10*L10*(M10*PF_WTG+N10*SQRT(1-PF_WTG^2))/(V_MV*1000) -> 0.0017027303 | P10: =3*G10^2*M10*L10/1000 -> 29.524969
A11: WF-01 | B11: 7 | C11: WF-01-T01 → SUBSTATION 34.5 kV BUS | D11: 7 | E11: =D11*P_WTG -> 26.6 | F11: =D11*WTG!$C$5 -> 28 | G11: =F11*1000000/(SQRT(3)*V_MV*1000) -> 468.57413 | H11: =G11/V_MIN -> 493.23593 | I11: =INDEX(SIZE_LIST,IFERROR(MATCH(H11-0.0001,GRP_AMP,1),0)+1) -> 1000 kcmil | J11: =INDEX(GRP_AMP,MATCH(I11,SIZE_LIST,0)) -> 524.03581 | K11: =H11/J11 -> 0.94122561 | L11: =L_HR -> 5 | M11: =INDEX(RAC_LIST,MATCH(I11,SIZE_LIST,0)) -> 0.075424919 | N11: =INDEX(X_LIST,MATCH(I11,SIZE_LIST,0)) -> 0.13107004 | O11: =SQRT(3)*G11*L11*(M11*PF_WTG+N11*SQRT(1-PF_WTG^2))/(V_MV*1000) -> 0.013241957 | P11: =3*G11^2*M11*L11/1000 -> 248.40637
A12: WF-01 TOTAL | E12: =MAX(E5:E11) -> 26.6 | G12: =MAX(G5:G11) -> 468.57413 | H12: =MAX(H5:H11) -> 493.23593 | O12: =SUM(O5:O11) -> 0.025728369 | P12: =SUM(P5:P11) -> 390.41874 | Q12: =P12/1000/E12 -> 0.014677396
A14: WF-02 | B14: 1 | C14: WF-02-T07 → WF-02-T06 | D14: 1 | E14: =D14*P_WTG -> 3.8 | F14: =D14*WTG!$C$5 -> 4 | G14: =F14*1000000/(SQRT(3)*V_MV*1000) -> 66.939162 | H14: =G14/V_MIN -> 70.462275 | I14: =INDEX(SIZE_LIST,IFERROR(MATCH(H14-0.0001,AMP_LIST,1),0)+1) -> 1/0 AWG | J14: =INDEX(AMP_LIST,MATCH(I14,SIZE_LIST,0)) -> 174.01904 | K14: =H14/J14 -> 0.4049113 | L14: =L_INT -> 0.616 | M14: =INDEX(RAC_LIST,MATCH(I14,SIZE_LIST,0)) -> 0.69119996 | N14: =INDEX(X_LIST,MATCH(I14,SIZE_LIST,0)) -> 0.18991836 | O14: =SQRT(3)*G14*L14*(M14*PF_WTG+N14*SQRT(1-PF_WTG^2))/(V_MV*1000) -> 0.0014821096 | P14: =3*G14^2*M14*L14/1000 -> 5.7235596
A15: WF-02 | B15: 2 | C15: WF-02-T06 → WF-02-T05 | D15: 2 | E15: =D15*P_WTG -> 7.6 | F15: =D15*WTG!$C$5 -> 8 | G15: =F15*1000000/(SQRT(3)*V_MV*1000) -> 133.87832 | H15: =G15/V_MIN -> 140.92455 | I15: =INDEX(SIZE_LIST,IFERROR(MATCH(H15-0.0001,AMP_LIST,1),0)+1) -> 1/0 AWG | J15: =INDEX(AMP_LIST,MATCH(I15,SIZE_LIST,0)) -> 174.01904 | K15: =H15/J15 -> 0.80982261 | L15: =L_INT -> 0.616 | M15: =INDEX(RAC_LIST,MATCH(I15,SIZE_LIST,0)) -> 0.69119996 | N15: =INDEX(X_LIST,MATCH(I15,SIZE_LIST,0)) -> 0.18991836 | O15: =SQRT(3)*G15*L15*(M15*PF_WTG+N15*SQRT(1-PF_WTG^2))/(V_MV*1000) -> 0.0029642192 | P15: =3*G15^2*M15*L15/1000 -> 22.894238
A16: WF-02 | B16: 3 | C16: WF-02-T05 → WF-02-T04 | D16: 3 | E16: =D16*P_WTG -> 11.4 | F16: =D16*WTG!$C$5 -> 12 | G16: =F16*1000000/(SQRT(3)*V_MV*1000) -> 200.81748 | H16: =G16/V_MIN -> 211.38683 | I16: =INDEX(SIZE_LIST,IFERROR(MATCH(H16-0.0001,AMP_LIST,1),0)+1) -> 4/0 AWG | J16: =INDEX(AMP_LIST,MATCH(I16,SIZE_LIST,0)) -> 253.13215 | K16: =H16/J16 -> 0.83508485 | L16: =L_INT -> 0.616 | M16: =INDEX(RAC_LIST,MATCH(I16,SIZE_LIST,0)) -> 0.34520816 | N16: =INDEX(X_LIST,MATCH(I16,SIZE_LIST,0)) -> 0.16995494 | O16: =SQRT(3)*G16*L16*(M16*PF_WTG+N16*SQRT(1-PF_WTG^2))/(V_MV*1000) -> 0.0023662856 | P16: =3*G16^2*M16*L16/1000 -> 25.726817
A17: WF-02 | B17: 4 | C17: WF-02-T04 → WF-02-T03 | D17: 4 | E17: =D17*P_WTG -> 15.2 | F17: =D17*WTG!$C$5 -> 16 | G17: =F17*1000000/(SQRT(3)*V_MV*1000) -> 267.75665 | H17: =G17/V_MIN -> 281.8491 | I17: =INDEX(SIZE_LIST,IFERROR(MATCH(H17-0.0001,AMP_LIST,1),0)+1) -> 350 kcmil | J17: =INDEX(AMP_LIST,MATCH(I17,SIZE_LIST,0)) -> 331.698 | K17: =H17/J17 -> 0.84971601 | L17: =L_INT -> 0.616 | M17: =INDEX(RAC_LIST,MATCH(I17,SIZE_LIST,0)) -> 0.20920489 | N17: =INDEX(X_LIST,MATCH(I17,SIZE_LIST,0)) -> 0.1561699 | O17: =SQRT(3)*G17*L17*(M17*PF_WTG+N17*SQRT(1-PF_WTG^2))/(V_MV*1000) -> 0.0020495237 | P17: =3*G17^2*M17*L17/1000 -> 27.717517
A18: WF-02 | B18: 5 | C18: WF-02-T03 → WF-02-T02 | D18: 5 | E18: =D18*P_WTG -> 19 | F18: =D18*WTG!$C$5 -> 20 | G18: =F18*1000000/(SQRT(3)*V_MV*1000) -> 334.69581 | H18: =G18/V_MIN -> 352.31138 | I18: =INDEX(SIZE_LIST,IFERROR(MATCH(H18-0.0001,AMP_LIST,1),0)+1) -> 500 kcmil | J18: =INDEX(AMP_LIST,MATCH(I18,SIZE_LIST,0)) -> 400.71111 | K18: =H18/J18 -> 0.87921539 | L18: =L_INT -> 0.616 | M18: =INDEX(RAC_LIST,MATCH(I18,SIZE_LIST,0)) -> 0.14697109 | N18: =INDEX(X_LIST,MATCH(I18,SIZE_LIST,0)) -> 0.14738241 | O18: =SQRT(3)*G18*L18*(M18*PF_WTG+N18*SQRT(1-PF_WTG^2))/(V_MV*1000) -> 0.001921544 | P18: =3*G18^2*M18*L18/1000 -> 30.425269
A19: WF-02 | B19: 6 | C19: WF-02-T02 → WF-02-T01 | D19: 6 | E19: =D19*P_WTG -> 22.8 | F19: =D19*WTG!$C$5 -> 24 | G19: =F19*1000000/(SQRT(3)*V_MV*1000) -> 401.63497 | H19: =G19/V_MIN -> 422.77365 | I19: =INDEX(SIZE_LIST,IFERROR(MATCH(H19-0.0001,AMP_LIST,1),0)+1) -> 750 kcmil | J19: =INDEX(AMP_LIST,MATCH(I19,SIZE_LIST,0)) -> 494.76038 | K19: =H19/J19 -> 0.85450184 | L19: =L_INT -> 0.616 | M19: =INDEX(RAC_LIST,MATCH(I19,SIZE_LIST,0)) -> 0.099043149 | N19: =INDEX(X_LIST,MATCH(I19,SIZE_LIST,0)) -> 0.13769322 | O19: =SQRT(3)*G19*L19*(M19*PF_WTG+N19*SQRT(1-PF_WTG^2))/(V_MV*1000) -> 0.0017027303 | P19: =3*G19^2*M19*L19/1000 -> 29.524969
A20: WF-02 | B20: 7 | C20: WF-02-T01 → SUBSTATION 34.5 kV BUS | D20: 7 | E20: =D20*P_WTG -> 26.6 | F20: =D20*WTG!$C$5 -> 28 | G20: =F20*1000000/(SQRT(3)*V_MV*1000) -> 468.57413 | H20: =G20/V_MIN -> 493.23593 | I20: =INDEX(SIZE_LIST,IFERROR(MATCH(H20-0.0001,GRP_AMP,1),0)+1) -> 1000 kcmil | J20: =INDEX(GRP_AMP,MATCH(I20,SIZE_LIST,0)) -> 524.03581 | K20: =H20/J20 -> 0.94122561 | L20: =L_HR -> 5 | M20: =INDEX(RAC_LIST,MATCH(I20,SIZE_LIST,0)) -> 0.075424919 | N20: =INDEX(X_LIST,MATCH(I20,SIZE_LIST,0)) -> 0.13107004 | O20: =SQRT(3)*G20*L20*(M20*PF_WTG+N20*SQRT(1-PF_WTG^2))/(V_MV*1000) -> 0.013241957 | P20: =3*G20^2*M20*L20/1000 -> 248.40637
A21: WF-02 TOTAL | E21: =MAX(E14:E20) -> 26.6 | G21: =MAX(G14:G20) -> 468.57413 | H21: =MAX(H14:H20) -> 493.23593 | O21: =SUM(O14:O20) -> 0.025728369 | P21: =SUM(P14:P20) -> 390.41874 | Q21: =P21/1000/E21 -> 0.014677396
A23: WF-03 | B23: 1 | C23: WF-03-T07 → WF-03-T06 | D23: 1 | E23: =D23*P_WTG -> 3.8 | F23: =D23*WTG!$C$5 -> 4 | G23: =F23*1000000/(SQRT(3)*V_MV*1000) -> 66.939162 | H23: =G23/V_MIN -> 70.462275 | I23: =INDEX(SIZE_LIST,IFERROR(MATCH(H23-0.0001,AMP_LIST,1),0)+1) -> 1/0 AWG | J23: =INDEX(AMP_LIST,MATCH(I23,SIZE_LIST,0)) -> 174.01904 | K23: =H23/J23 -> 0.4049113 | L23: =L_INT -> 0.616 | M23: =INDEX(RAC_LIST,MATCH(I23,SIZE_LIST,0)) -> 0.69119996 | N23: =INDEX(X_LIST,MATCH(I23,SIZE_LIST,0)) -> 0.18991836 | O23: =SQRT(3)*G23*L23*(M23*PF_WTG+N23*SQRT(1-PF_WTG^2))/(V_MV*1000) -> 0.0014821096 | P23: =3*G23^2*M23*L23/1000 -> 5.7235596
A24: WF-03 | B24: 2 | C24: WF-03-T06 → WF-03-T05 | D24: 2 | E24: =D24*P_WTG -> 7.6 | F24: =D24*WTG!$C$5 -> 8 | G24: =F24*1000000/(SQRT(3)*V_MV*1000) -> 133.87832 | H24: =G24/V_MIN -> 140.92455 | I24: =INDEX(SIZE_LIST,IFERROR(MATCH(H24-0.0001,AMP_LIST,1),0)+1) -> 1/0 AWG | J24: =INDEX(AMP_LIST,MATCH(I24,SIZE_LIST,0)) -> 174.01904 | K24: =H24/J24 -> 0.80982261 | L24: =L_INT -> 0.616 | M24: =INDEX(RAC_LIST,MATCH(I24,SIZE_LIST,0)) -> 0.69119996 | N24: =INDEX(X_LIST,MATCH(I24,SIZE_LIST,0)) -> 0.18991836 | O24: =SQRT(3)*G24*L24*(M24*PF_WTG+N24*SQRT(1-PF_WTG^2))/(V_MV*1000) -> 0.0029642192 | P24: =3*G24^2*M24*L24/1000 -> 22.894238
A25: WF-03 | B25: 3 | C25: WF-03-T05 → WF-03-T04 | D25: 3 | E25: =D25*P_WTG -> 11.4 | F25: =D25*WTG!$C$5 -> 12 | G25: =F25*1000000/(SQRT(3)*V_MV*1000) -> 200.81748 | H25: =G25/V_MIN -> 211.38683 | I25: =INDEX(SIZE_LIST,IFERROR(MATCH(H25-0.0001,AMP_LIST,1),0)+1) -> 4/0 AWG | J25: =INDEX(AMP_LIST,MATCH(I25,SIZE_LIST,0)) -> 253.13215 | K25: =H25/J25 -> 0.83508485 | L25: =L_INT -> 0.616 | M25: =INDEX(RAC_LIST,MATCH(I25,SIZE_LIST,0)) -> 0.34520816 | N25: =INDEX(X_LIST,MATCH(I25,SIZE_LIST,0)) -> 0.16995494 | O25: =SQRT(3)*G25*L25*(M25*PF_WTG+N25*SQRT(1-PF_WTG^2))/(V_MV*1000) -> 0.0023662856 | P25: =3*G25^2*M25*L25/1000 -> 25.726817
A26: WF-03 | B26: 4 | C26: WF-03-T04 → WF-03-T03 | D26: 4 | E26: =D26*P_WTG -> 15.2 | F26: =D26*WTG!$C$5 -> 16 | G26: =F26*1000000/(SQRT(3)*V_MV*1000) -> 267.75665 | H26: =G26/V_MIN -> 281.8491 | I26: =INDEX(SIZE_LIST,IFERROR(MATCH(H26-0.0001,AMP_LIST,1),0)+1) -> 350 kcmil | J26: =INDEX(AMP_LIST,MATCH(I26,SIZE_LIST,0)) -> 331.698 | K26: =H26/J26 -> 0.84971601 | L26: =L_INT -> 0.616 | M26: =INDEX(RAC_LIST,MATCH(I26,SIZE_LIST,0)) -> 0.20920489 | N26: =INDEX(X_LIST,MATCH(I26,SIZE_LIST,0)) -> 0.1561699 | O26: =SQRT(3)*G26*L26*(M26*PF_WTG+N26*SQRT(1-PF_WTG^2))/(V_MV*1000) -> 0.0020495237 | P26: =3*G26^2*M26*L26/1000 -> 27.717517
A27: WF-03 | B27: 5 | C27: WF-03-T03 → WF-03-T02 | D27: 5 | E27: =D27*P_WTG -> 19 | F27: =D27*WTG!$C$5 -> 20 | G27: =F27*1000000/(SQRT(3)*V_MV*1000) -> 334.69581 | H27: =G27/V_MIN -> 352.31138 | I27: =INDEX(SIZE_LIST,IFERROR(MATCH(H27-0.0001,AMP_LIST,1),0)+1) -> 500 kcmil | J27: =INDEX(AMP_LIST,MATCH(I27,SIZE_LIST,0)) -> 400.71111 | K27: =H27/J27 -> 0.87921539 | L27: =L_INT -> 0.616 | M27: =INDEX(RAC_LIST,MATCH(I27,SIZE_LIST,0)) -> 0.14697109 | N27: =INDEX(X_LIST,MATCH(I27,SIZE_LIST,0)) -> 0.14738241 | O27: =SQRT(3)*G27*L27*(M27*PF_WTG+N27*SQRT(1-PF_WTG^2))/(V_MV*1000) -> 0.001921544 | P27: =3*G27^2*M27*L27/1000 -> 30.425269
A28: WF-03 | B28: 6 | C28: WF-03-T02 → WF-03-T01 | D28: 6 | E28: =D28*P_WTG -> 22.8 | F28: =D28*WTG!$C$5 -> 24 | G28: =F28*1000000/(SQRT(3)*V_MV*1000) -> 401.63497 | H28: =G28/V_MIN -> 422.77365 | I28: =INDEX(SIZE_LIST,IFERROR(MATCH(H28-0.0001,AMP_LIST,1),0)+1) -> 750 kcmil | J28: =INDEX(AMP_LIST,MATCH(I28,SIZE_LIST,0)) -> 494.76038 | K28: =H28/J28 -> 0.85450184 | L28: =L_INT -> 0.616 | M28: =INDEX(RAC_LIST,MATCH(I28,SIZE_LIST,0)) -> 0.099043149 | N28: =INDEX(X_LIST,MATCH(I28,SIZE_LIST,0)) -> 0.13769322 | O28: =SQRT(3)*G28*L28*(M28*PF_WTG+N28*SQRT(1-PF_WTG^2))/(V_MV*1000) -> 0.0017027303 | P28: =3*G28^2*M28*L28/1000 -> 29.524969
A29: WF-03 | B29: 7 | C29: WF-03-T01 → SUBSTATION 34.5 kV BUS | D29: 7 | E29: =D29*P_WTG -> 26.6 | F29: =D29*WTG!$C$5 -> 28 | G29: =F29*1000000/(SQRT(3)*V_MV*1000) -> 468.57413 | H29: =G29/V_MIN -> 493.23593 | I29: =INDEX(SIZE_LIST,IFERROR(MATCH(H29-0.0001,GRP_AMP,1),0)+1) -> 1000 kcmil | J29: =INDEX(GRP_AMP,MATCH(I29,SIZE_LIST,0)) -> 524.03581 | K29: =H29/J29 -> 0.94122561 | L29: =L_HR -> 5 | M29: =INDEX(RAC_LIST,MATCH(I29,SIZE_LIST,0)) -> 0.075424919 | N29: =INDEX(X_LIST,MATCH(I29,SIZE_LIST,0)) -> 0.13107004 | O29: =SQRT(3)*G29*L29*(M29*PF_WTG+N29*SQRT(1-PF_WTG^2))/(V_MV*1000) -> 0.013241957 | P29: =3*G29^2*M29*L29/1000 -> 248.40637
A30: WF-03 TOTAL | E30: =MAX(E23:E29) -> 26.6 | G30: =MAX(G23:G29) -> 468.57413 | H30: =MAX(H23:H29) -> 493.23593 | O30: =SUM(O23:O29) -> 0.025728369 | P30: =SUM(P23:P29) -> 390.41874 | Q30: =P30/1000/E30 -> 0.014677396
A32: WF-04 | B32: 1 | C32: WF-04-T06 → WF-04-T05 | D32: 1 | E32: =D32*P_WTG -> 3.8 | F32: =D32*WTG!$C$5 -> 4 | G32: =F32*1000000/(SQRT(3)*V_MV*1000) -> 66.939162 | H32: =G32/V_MIN -> 70.462275 | I32: =INDEX(SIZE_LIST,IFERROR(MATCH(H32-0.0001,AMP_LIST,1),0)+1) -> 1/0 AWG | J32: =INDEX(AMP_LIST,MATCH(I32,SIZE_LIST,0)) -> 174.01904 | K32: =H32/J32 -> 0.4049113 | L32: =L_INT -> 0.616 | M32: =INDEX(RAC_LIST,MATCH(I32,SIZE_LIST,0)) -> 0.69119996 | N32: =INDEX(X_LIST,MATCH(I32,SIZE_LIST,0)) -> 0.18991836 | O32: =SQRT(3)*G32*L32*(M32*PF_WTG+N32*SQRT(1-PF_WTG^2))/(V_MV*1000) -> 0.0014821096 | P32: =3*G32^2*M32*L32/1000 -> 5.7235596
A33: WF-04 | B33: 2 | C33: WF-04-T05 → WF-04-T04 | D33: 2 | E33: =D33*P_WTG -> 7.6 | F33: =D33*WTG!$C$5 -> 8 | G33: =F33*1000000/(SQRT(3)*V_MV*1000) -> 133.87832 | H33: =G33/V_MIN -> 140.92455 | I33: =INDEX(SIZE_LIST,IFERROR(MATCH(H33-0.0001,AMP_LIST,1),0)+1) -> 1/0 AWG | J33: =INDEX(AMP_LIST,MATCH(I33,SIZE_LIST,0)) -> 174.01904 | K33: =H33/J33 -> 0.80982261 | L33: =L_INT -> 0.616 | M33: =INDEX(RAC_LIST,MATCH(I33,SIZE_LIST,0)) -> 0.69119996 | N33: =INDEX(X_LIST,MATCH(I33,SIZE_LIST,0)) -> 0.18991836 | O33: =SQRT(3)*G33*L33*(M33*PF_WTG+N33*SQRT(1-PF_WTG^2))/(V_MV*1000) -> 0.0029642192 | P33: =3*G33^2*M33*L33/1000 -> 22.894238
A34: WF-04 | B34: 3 | C34: WF-04-T04 → WF-04-T03 | D34: 3 | E34: =D34*P_WTG -> 11.4 | F34: =D34*WTG!$C$5 -> 12 | G34: =F34*1000000/(SQRT(3)*V_MV*1000) -> 200.81748 | H34: =G34/V_MIN -> 211.38683 | I34: =INDEX(SIZE_LIST,IFERROR(MATCH(H34-0.0001,AMP_LIST,1),0)+1) -> 4/0 AWG | J34: =INDEX(AMP_LIST,MATCH(I34,SIZE_LIST,0)) -> 253.13215 | K34: =H34/J34 -> 0.83508485 | L34: =L_INT -> 0.616 | M34: =INDEX(RAC_LIST,MATCH(I34,SIZE_LIST,0)) -> 0.34520816 | N34: =INDEX(X_LIST,MATCH(I34,SIZE_LIST,0)) -> 0.16995494 | O34: =SQRT(3)*G34*L34*(M34*PF_WTG+N34*SQRT(1-PF_WTG^2))/(V_MV*1000) -> 0.0023662856 | P34: =3*G34^2*M34*L34/1000 -> 25.726817
A35: WF-04 | B35: 4 | C35: WF-04-T03 → WF-04-T02 | D35: 4 | E35: =D35*P_WTG -> 15.2 | F35: =D35*WTG!$C$5 -> 16 | G35: =F35*1000000/(SQRT(3)*V_MV*1000) -> 267.75665 | H35: =G35/V_MIN -> 281.8491 | I35: =INDEX(SIZE_LIST,IFERROR(MATCH(H35-0.0001,AMP_LIST,1),0)+1) -> 350 kcmil | J35: =INDEX(AMP_LIST,MATCH(I35,SIZE_LIST,0)) -> 331.698 | K35: =H35/J35 -> 0.84971601 | L35: =L_INT -> 0.616 | M35: =INDEX(RAC_LIST,MATCH(I35,SIZE_LIST,0)) -> 0.20920489 | N35: =INDEX(X_LIST,MATCH(I35,SIZE_LIST,0)) -> 0.1561699 | O35: =SQRT(3)*G35*L35*(M35*PF_WTG+N35*SQRT(1-PF_WTG^2))/(V_MV*1000) -> 0.0020495237 | P35: =3*G35^2*M35*L35/1000 -> 27.717517
A36: WF-04 | B36: 5 | C36: WF-04-T02 → WF-04-T01 | D36: 5 | E36: =D36*P_WTG -> 19 | F36: =D36*WTG!$C$5 -> 20 | G36: =F36*1000000/(SQRT(3)*V_MV*1000) -> 334.69581 | H36: =G36/V_MIN -> 352.31138 | I36: =INDEX(SIZE_LIST,IFERROR(MATCH(H36-0.0001,AMP_LIST,1),0)+1) -> 500 kcmil | J36: =INDEX(AMP_LIST,MATCH(I36,SIZE_LIST,0)) -> 400.71111 | K36: =H36/J36 -> 0.87921539 | L36: =L_INT -> 0.616 | M36: =INDEX(RAC_LIST,MATCH(I36,SIZE_LIST,0)) -> 0.14697109 | N36: =INDEX(X_LIST,MATCH(I36,SIZE_LIST,0)) -> 0.14738241 | O36: =SQRT(3)*G36*L36*(M36*PF_WTG+N36*SQRT(1-PF_WTG^2))/(V_MV*1000) -> 0.001921544 | P36: =3*G36^2*M36*L36/1000 -> 30.425269
A37: WF-04 | B37: 6 | C37: WF-04-T01 → SUBSTATION 34.5 kV BUS | D37: 6 | E37: =D37*P_WTG -> 22.8 | F37: =D37*WTG!$C$5 -> 24 | G37: =F37*1000000/(SQRT(3)*V_MV*1000) -> 401.63497 | H37: =G37/V_MIN -> 422.77365 | I37: =INDEX(SIZE_LIST,IFERROR(MATCH(H37-0.0001,GRP_AMP,1),0)+1) -> 750 kcmil | J37: =INDEX(GRP_AMP,MATCH(I37,SIZE_LIST,0)) -> 454.52401 | K37: =H37/J37 -> 0.93014591 | L37: =L_HR -> 5 | M37: =INDEX(RAC_LIST,MATCH(I37,SIZE_LIST,0)) -> 0.099043149 | N37: =INDEX(X_LIST,MATCH(I37,SIZE_LIST,0)) -> 0.13769322 | O37: =SQRT(3)*G37*L37*(M37*PF_WTG+N37*SQRT(1-PF_WTG^2))/(V_MV*1000) -> 0.013820863 | P37: =3*G37^2*M37*L37/1000 -> 239.65072
A38: WF-04 TOTAL | E38: =MAX(E32:E37) -> 22.8 | G38: =MAX(G32:G37) -> 401.63497 | H38: =MAX(H32:H37) -> 422.77365 | O38: =SUM(O32:O37) -> 0.024604545 | P38: =SUM(P32:P37) -> 352.13812 | Q38: =P38/1000/E38 -> 0.015444654
A40: Sum of feeder P (MW) | E40: =E12+E21+E30+E38 -> 102.6
A41: Sum of feeder I @1.0 pu (A) | G41: =G12+G21+G30+G38 -> 1807.3574
A42: WTG count check | D42: =N_F1+N_F2+N_F3+N_F4 -> 27 | E42: =IF(D42=N_WTG,"OK — 27 WTGs","ERROR") -> OK — 27 WTGs
A44: Section k carries k WTGs; k = n is the home-run into the substation. ΔV is the steady-state voltage rise from the bus to the remote WTG at PF_WTG (lagging export).
A45: Home-run sizing within the substation approach corridor is governed by mutual heating — home-run (k = n) is sized against the 4-circuit/2.0 m grouped ampacity on sheet "Cable_Sensitivity" (named range GRP_AMP).
A46: Lengths are ILLUSTRATIVE ONLY (no layout provided). Replace L_INT/L_HR or enter per-section lengths in column L when the layout is issued.

Sheet Cable_Sensitivity
A1: Ampacity sensitivity to soil resistivity and 4-circuit grouping (computed by calc.py — same IEC 60287 model)
A2: PRELIMINARY ENGINEERING — NOT FOR CONSTRUCTION | Rev P0 | 2026-10-13
A4: Case | B4: 1/0 AWG | C4: 4/0 AWG | D4: 350 kcmil | E4: 500 kcmil | F4: 750 kcmil | G4: 1000 kcmil | H4: 1250 kcmil
A5: Single circuit, ρ = 0.9 K·m/W | B5: 193 | C5: 282 | D5: 371 | E5: 449 | F5: 556 | G5: 645 | H5: 719
A6: Single circuit, ρ = 1.0 K·m/W | B6: 186 | C6: 271 | D6: 356 | E6: 431 | F6: 533 | G6: 617 | H6: 688
A7: Single circuit, ρ = 1.2 K·m/W | B7: 174 | C7: 253 | D7: 332 | E7: 401 | F7: 495 | G7: 572 | H7: 637
A8: Single circuit, ρ = 1.5 K·m/W | B8: 160 | C8: 232 | D8: 303 | E8: 365 | F8: 450 | G8: 519 | H8: 578
A9: Single circuit, ρ = 2.0 K·m/W | B9: 142 | C9: 206 | D9: 268 | E9: 322 | F9: 396 | G9: 457 | H9: 507
A10: 4 trefoils flat, 1.0 m spacing, ρ = 1.2 (centre circuit) | B10: 149 | C10: 215 | D10: 279 | E10: 335 | F10: 411 | G10: 472 | H10: 524
A11: 4 trefoils flat, 2.0 m spacing, ρ = 1.2 (centre circuit) | B11: 162 | C11: 235 | D11: 307 | E11: 369 | F11: 455 | G11: 524 | H11: 582
A12: 4 trefoils flat, 3.0 m spacing, ρ = 1.2 (centre circuit) | B12: 168 | C12: 243 | D12: 318 | E12: 383 | F12: 472 | G12: 545 | H12: 607
A14: Values in amperes; 90 °C conductor, 25 °C ambient, 1.0 m depth, 100 % LF. Static values — regenerate with calc.py if inputs change.

Sheet SC_Withstand
A1: Short-circuit withstand — ICEA P-32-382 adiabatic method
A2: PRELIMINARY ENGINEERING — NOT FOR CONSTRUCTION | Rev P0 | 2026-10-13
A4: Conductor (Al): (I/A)²·t = 0.0125·log10[(T2+228)/(T1+228)], A in cmil, T1 = 90 °C, T2 = 250 °C
A5: Screen (Cu), ICEA P-45-482 simplified adiabatic: (I/A)²·t = 0.0297·log10[(T2+234)/(T1+234)], T1 = 80 °C, T2 = 200 °C (jacket-limited, confirm with vendor)
A7: Size | B7: A (kcmil) | C7: I @0.10 s (kA) | D7: I @0.25 s (kA) | E7: I @0.50 s (kA) | F7: I @1.0 s (kA)
A8: 1/0 AWG | B8: =Cable_Ampacity!B5*1.973525 -> 105.56385 | C8: =B8*1000*SQRT(0.0125*LOG10((250+228)/(90+228))/0.1)/1000 -> 15.702103 | D8: =B8*1000*SQRT(0.0125*LOG10((250+228)/(90+228))/0.25)/1000 -> 9.9308819 | E8: =B8*1000*SQRT(0.0125*LOG10((250+228)/(90+228))/0.5)/1000 -> 7.022194 | F8: =B8*1000*SQRT(0.0125*LOG10((250+228)/(90+228))/1)/1000 -> 4.965441
A9: 4/0 AWG | B9: =Cable_Ampacity!B6*1.973525 -> 211.56188 | C9: =B9*1000*SQRT(0.0125*LOG10((250+228)/(90+228))/0.1)/1000 -> 31.468788 | D9: =B9*1000*SQRT(0.0125*LOG10((250+228)/(90+228))/0.25)/1000 -> 19.902609 | E9: =B9*1000*SQRT(0.0125*LOG10((250+228)/(90+228))/0.5)/1000 -> 14.07327 | F9: =B9*1000*SQRT(0.0125*LOG10((250+228)/(90+228))/1)/1000 -> 9.9513044
A10: 350 kcmil | B10: =Cable_Ampacity!B7*1.973525 -> 349.90598 | C10: =B10*1000*SQRT(0.0125*LOG10((250+228)/(90+228))/0.1)/1000 -> 52.046791 | D10: =B10*1000*SQRT(0.0125*LOG10((250+228)/(90+228))/0.25)/1000 -> 32.917281 | E10: =B10*1000*SQRT(0.0125*LOG10((250+228)/(90+228))/0.5)/1000 -> 23.276033 | F10: =B10*1000*SQRT(0.0125*LOG10((250+228)/(90+228))/1)/1000 -> 16.458641
A11: 500 kcmil | B11: =Cable_Ampacity!B8*1.973525 -> 500.09123 | C11: =B11*1000*SQRT(0.0125*LOG10((250+228)/(90+228))/0.1)/1000 -> 74.386108 | D11: =B11*1000*SQRT(0.0125*LOG10((250+228)/(90+228))/0.25)/1000 -> 47.045905 | E11: =B11*1000*SQRT(0.0125*LOG10((250+228)/(90+228))/0.5)/1000 -> 33.266479 | F11: =B11*1000*SQRT(0.0125*LOG10((250+228)/(90+228))/1)/1000 -> 23.522953
A12: 750 kcmil | B12: =Cable_Ampacity!B9*1.973525 -> 749.9395 | C12: =B12*1000*SQRT(0.0125*LOG10((250+228)/(90+228))/0.1)/1000 -> 111.54981 | D12: =B12*1000*SQRT(0.0125*LOG10((250+228)/(90+228))/0.25)/1000 -> 70.550292 | E12: =B12*1000*SQRT(0.0125*LOG10((250+228)/(90+228))/0.5)/1000 -> 49.88659 | F12: =B12*1000*SQRT(0.0125*LOG10((250+228)/(90+228))/1)/1000 -> 35.275146
A13: 1000 kcmil | B13: =Cable_Ampacity!B10*1.973525 -> 999.98512 | C13: =B13*1000*SQRT(0.0125*LOG10((250+228)/(90+228))/0.1)/1000 -> 148.74286 | D13: =B13*1000*SQRT(0.0125*LOG10((250+228)/(90+228))/0.25)/1000 -> 94.073245 | E13: =B13*1000*SQRT(0.0125*LOG10((250+228)/(90+228))/0.5)/1000 -> 66.519829 | F13: =B13*1000*SQRT(0.0125*LOG10((250+228)/(90+228))/1)/1000 -> 47.036622
A14: 1250 kcmil | B14: =Cable_Ampacity!B11*1.973525 -> 1250.0307 | C14: =B14*1000*SQRT(0.0125*LOG10((250+228)/(90+228))/0.1)/1000 -> 185.93591 | D14: =B14*1000*SQRT(0.0125*LOG10((250+228)/(90+228))/0.25)/1000 -> 117.5962 | E14: =B14*1000*SQRT(0.0125*LOG10((250+228)/(90+228))/0.5)/1000 -> 83.153069 | F14: =B14*1000*SQRT(0.0125*LOG10((250+228)/(90+228))/1)/1000 -> 58.798099
A17: Screen withstand (kA) for As (mm²) = | C17: =Cable_Ampacity!R5 -> 36.413336
C18: t = 0.10 s | D18: t = 0.25 s | E18: t = 0.50 s | F18: t = 1.0 s
C19: =$C$17*1.973525*1000*SQRT(0.0297*LOG10((200+234)/(80+234))/0.1)/1000 -> 14.682916 | D19: =$C$17*1.973525*1000*SQRT(0.0297*LOG10((200+234)/(80+234))/0.25)/1000 -> 9.2862916 | E19: =$C$17*1.973525*1000*SQRT(0.0297*LOG10((200+234)/(80+234))/0.5)/1000 -> 6.5663998 | F19: =$C$17*1.973525*1000*SQRT(0.0297*LOG10((200+234)/(80+234))/1)/1000 -> 4.6431458
A21: Required Cu screen area (mm²) | B21: I_fault (kA) | C21: t = 0.25 s | D21: t = 0.50 s | E21: t = 1.0 s
B22: 5 | C22: =B22*1000/SQRT(0.0297*LOG10((200+234)/(80+234))/0.25)/1973.525 -> 19.605962 | D22: =B22*1000/SQRT(0.0297*LOG10((200+234)/(80+234))/0.5)/1973.525 -> 27.727017 | E22: =B22*1000/SQRT(0.0297*LOG10((200+234)/(80+234))/1)/1973.525 -> 39.211924
B23: 10 | C23: =B23*1000/SQRT(0.0297*LOG10((200+234)/(80+234))/0.25)/1973.525 -> 39.211924 | D23: =B23*1000/SQRT(0.0297*LOG10((200+234)/(80+234))/0.5)/1973.525 -> 55.454034 | E23: =B23*1000/SQRT(0.0297*LOG10((200+234)/(80+234))/1)/1973.525 -> 78.423847
B24: 15 | C24: =B24*1000/SQRT(0.0297*LOG10((200+234)/(80+234))/0.25)/1973.525 -> 58.817885 | D24: =B24*1000/SQRT(0.0297*LOG10((200+234)/(80+234))/0.5)/1973.525 -> 83.181051 | E24: =B24*1000/SQRT(0.0297*LOG10((200+234)/(80+234))/1)/1973.525 -> 117.63577
B25: 20 | C25: =B25*1000/SQRT(0.0297*LOG10((200+234)/(80+234))/0.25)/1973.525 -> 78.423847 | D25: =B25*1000/SQRT(0.0297*LOG10((200+234)/(80+234))/0.5)/1973.525 -> 110.90807 | E25: =B25*1000/SQRT(0.0297*LOG10((200+234)/(80+234))/1)/1973.525 -> 156.84769
A27: Ground-fault current at the 34.5 kV bus and its division between screen, counterpoise and earth are NOT KNOWN — requires short-circuit study and grounding-transformer selection.

Sheet BESS_Feeders
A1: BESS feeder currents (4 existing feeders) — PCS configuration not provided
A2: PRELIMINARY ENGINEERING — NOT FOR CONSTRUCTION | Rev P0 | 2026-10-13
A4: Quantity | B4: Equation | C4: Value | D4: Unit
A5: BESS S at MV (screening) | B5: S = P/PF | C5: =P_BESS/PF_BESS -> 105.26316 | D5: MVA
A6: Per-feeder P | B6: P/N | C6: =P_BESS/N_BF -> 25 | D6: MW
A7: Per-feeder S | B7: S/N | C7: =C5/N_BF -> 26.315789 | D7: MVA
A8: Per-feeder current @1.0 pu | B8: S/(√3V) | C8: =C7*1000000/(SQRT(3)*V_MV*1000) -> 440.38922 | D8: A
A9: Per-feeder current @V_MIN | C9: =C8/V_MIN -> 463.5676 | D9: A
A10: Total BESS current @1.0 pu | C10: =C5*1000000/(SQRT(3)*V_MV*1000) -> 1761.5569 | D10: A
A11: Duration at rated power | B11: E/P | C11: =E_BESS/P_BESS -> 2 | D11: h
A13: Actual-PCS method (to be completed when BESS design data are released):
A14: Feeder | B14: No. PCS/MVT blocks (O) | C14: PCS rating each (MVA) (O) | D14: Feeder S (MVA) | E14: Feeder I @1.0 pu (A) | F14: Feeder I @V_MIN (A)
A15: BF-01 | D15: =B15*C15 -> 0 | E15: =D15*1000000/(SQRT(3)*V_MV*1000) -> 0 | F15: =E15/V_MIN -> 0
A16: BF-02 | D16: =B16*C16 -> 0 | E16: =D16*1000000/(SQRT(3)*V_MV*1000) -> 0 | F16: =E16/V_MIN -> 0
A17: BF-03 | D17: =B17*C17 -> 0 | E17: =D17*1000000/(SQRT(3)*V_MV*1000) -> 0 | F17: =E17/V_MIN -> 0
A18: BF-04 | D18: =B18*C18 -> 0 | E18: =D18*1000000/(SQRT(3)*V_MV*1000) -> 0 | F18: =E18/V_MIN -> 0

Sheet GSU_Sizing
A1: GSU sizing at 100 MW POI export/import with ±0.95 PF at high side (candidate 125 MVA)
A2: PRELIMINARY ENGINEERING — NOT FOR CONSTRUCTION | Rev P0 | 2026-10-13
A4: Quantity | B4: Equation | C4: Value | D4: Unit
A5: Q required at HV (each direction) | B5: Q = P·tan(acos PF) | C5: =P_EXP*TAN(ACOS(PF_POI)) -> 32.868411 | D5: Mvar
A6: S at HV | B6: √(P²+Q²) | C6: =SQRT(P_EXP^2+C5^2) -> 105.26316 | D6: MVA
A7: GSU HV rated current | B7: S_GSU/(√3·115) | C7: =S_GSU*1000000/(SQRT(3)*V_HV*1000) -> 627.55464 | D7: A
A8: GSU MV rated current | B8: S_GSU/(√3·34.5) | C8: =S_GSU*1000000/(SQRT(3)*V_MV*1000) -> 2091.8488 | D8: A
A9: GSU MV current @V_MIN | C9: =C8/V_MIN -> 2201.9461 | D9: A
A10: Max POI current @0.95 pu | B10: S_HV/(√3·0.95·115) | C10: =C6*1000000/(SQRT(3)*0.95*V_HV*1000) -> 556.28112 | D10: A
A11: Infinite-bus 3φ fault via GSU at MV | B11: I_MV,r / Z | C11: =C8/Z_GSU/1000 -> 20.918488 | D11: kA
A12: Infinite-bus 3φ fault via GSU at HV (grid side excluded) | B12: I_HV,r / Z | C12: =C7/Z_GSU/1000 -> 6.2755464 | D12: kA
A15: V_HV (pu) | B15: Q sign (+ supply / − absorb) | C15: P_HV (MW) | D15: Q_HV (Mvar) | E15: I (pu of S_GSU) | F15: Equivalent MVA | G15: Loading % | H15: Q loss (Mvar) | I15: P loss (MW) | J15: P_MV (MW) | K15: Q_MV (Mvar) | L15: S_MV (MVA)
A16: 0.95 | B16: 1 | C16: =P_EXP -> 100 | D16: =B16*$C$5 -> 32.868411 | E16: =$C$6/(A16*S_GSU) -> 0.88642659 | F16: =E16*S_GSU -> 110.80332 | G16: =E16 -> 0.88642659 | H16: =E16^2*Z_GSU*S_GSU -> 9.8219013 | I16: =E16^2*PCU_GSU*S_GSU -> 0.39287605 | J16: =C16+I16 -> 100.39288 | K16: =D16+H16 -> 42.690312 | L16: =SQRT(J16^2+K16^2) -> 109.09259
A17: 0.95 | B17: -1 | C17: =P_EXP -> 100 | D17: =B17*$C$5 -> -32.868411 | E17: =$C$6/(A17*S_GSU) -> 0.88642659 | F17: =E17*S_GSU -> 110.80332 | G17: =E17 -> 0.88642659 | H17: =E17^2*Z_GSU*S_GSU -> 9.8219013 | I17: =E17^2*PCU_GSU*S_GSU -> 0.39287605 | J17: =C17+I17 -> 100.39288 | K17: =D17+H17 -> -23.046509 | L17: =SQRT(J17^2+K17^2) -> 103.00423
A18: 1 | B18: 1 | C18: =P_EXP -> 100 | D18: =B18*$C$5 -> 32.868411 | E18: =$C$6/(A18*S_GSU) -> 0.84210526 | F18: =E18*S_GSU -> 105.26316 | G18: =E18 -> 0.84210526 | H18: =E18^2*Z_GSU*S_GSU -> 8.8642659 | I18: =E18^2*PCU_GSU*S_GSU -> 0.35457064 | J18: =C18+I18 -> 100.35457 | K18: =D18+H18 -> 41.732676 | L18: =SQRT(J18^2+K18^2) -> 108.68604
A19: 1 | B19: -1 | C19: =P_EXP -> 100 | D19: =B19*$C$5 -> -32.868411 | E19: =$C$6/(A19*S_GSU) -> 0.84210526 | F19: =E19*S_GSU -> 105.26316 | G19: =E19 -> 0.84210526 | H19: =E19^2*Z_GSU*S_GSU -> 8.8642659 | I19: =E19^2*PCU_GSU*S_GSU -> 0.35457064 | J19: =C19+I19 -> 100.35457 | K19: =D19+H19 -> -24.004145 | L19: =SQRT(J19^2+K19^2) -> 103.18546
A20: 1.05 | B20: 1 | C20: =P_EXP -> 100 | D20: =B20*$C$5 -> 32.868411 | E20: =$C$6/(A20*S_GSU) -> 0.80200501 | F20: =E20*S_GSU -> 100.25063 | G20: =E20 -> 0.80200501 | H20: =E20^2*Z_GSU*S_GSU -> 8.0401505 | I20: =E20^2*PCU_GSU*S_GSU -> 0.32160602 | J20: =C20+I20 -> 100.32161 | K20: =D20+H20 -> 40.908561 | L20: =SQRT(J20^2+K20^2) -> 108.34175
A21: 1.05 | B21: -1 | C21: =P_EXP -> 100 | D21: =B21*$C$5 -> -32.868411 | E21: =$C$6/(A21*S_GSU) -> 0.80200501 | F21: =E21*S_GSU -> 100.25063 | G21: =E21 -> 0.80200501 | H21: =E21^2*Z_GSU*S_GSU -> 8.0401505 | I21: =E21^2*PCU_GSU*S_GSU -> 0.32160602 | J21: =C21+I21 -> 100.32161 | K21: =D21+H21 -> -24.82826 | L21: =SQRT(J21^2+K21^2) -> 103.34828
A23: Max equivalent MVA | F23: =MAX(F16:F21) -> 110.80332
A24: Margin of S_GSU over max equivalent MVA | F24: =S_GSU/F23-1 -> 0.128125
A25: Import (charging) case: identical |S| at HV ⇒ same current loading; Q-loss sign convention unchanged.
A26: Equivalent MVA = I × √3 × V_rated (thermal duty is current-driven).
A28: Alternative top rating (MVA) | B28: Loading @ 0.95 pu, 0.95 PF
A29: 100 | B29: =$F$23/A29 -> 1.1080332
A30: 112 | B30: =$F$23/A30 -> 0.98931539
A31: 115 | B31: =$F$23/A31 -> 0.96350717
A32: 125 | B32: =$F$23/A32 -> 0.88642659
A33: 140 | B33: =$F$23/A33 -> 0.79145231

Sheet Fault_Screening
A1: 34.5 kV bus three-phase fault screening (parametric — utility fault data not provided)
A2: PRELIMINARY ENGINEERING — NOT FOR CONSTRUCTION | Rev P0 | 2026-10-13
A4: S_sc grid (MVA) | B4: Z_GSU (pu) | C4: Z_sys (pu on S_GSU) | D4: I grid via GSU (kA) | E4: I wind (kA) | F4: I BESS (kA) | G4: I total (kA) | H4: vs 40 kA
A5: 2000 | B5: 0.08 | C5: =S_GSU/A5 -> 0.0625 | D5: =GSU_Sizing!$C$8/(C5+B5)/1000 -> 14.679641 | E5: =K_DFIG*WTG!$C$16/1000 -> 9.0367868 | F5: =K_IBR*BESS_Feeders!$C$10/1000 -> 2.1138683 | G5: =D5+E5+F5 -> 25.830296 | H5: =IF(G5<=40,"≤ 40 kA","EXCEEDS") -> ≤ 40 kA
A6: 2000 | B6: 0.1 | C6: =S_GSU/A6 -> 0.0625 | D6: =GSU_Sizing!$C$8/(C6+B6)/1000 -> 12.872916 | E6: =K_DFIG*WTG!$C$16/1000 -> 9.0367868 | F6: =K_IBR*BESS_Feeders!$C$10/1000 -> 2.1138683 | G6: =D6+E6+F6 -> 24.023571 | H6: =IF(G6<=40,"≤ 40 kA","EXCEEDS") -> ≤ 40 kA
A7: 2000 | B7: 0.12 | C7: =S_GSU/A7 -> 0.0625 | D7: =GSU_Sizing!$C$8/(C7+B7)/1000 -> 11.462185 | E7: =K_DFIG*WTG!$C$16/1000 -> 9.0367868 | F7: =K_IBR*BESS_Feeders!$C$10/1000 -> 2.1138683 | G7: =D7+E7+F7 -> 22.61284 | H7: =IF(G7<=40,"≤ 40 kA","EXCEEDS") -> ≤ 40 kA
A8: 4000 | B8: 0.08 | C8: =S_GSU/A8 -> 0.03125 | D8: =GSU_Sizing!$C$8/(C8+B8)/1000 -> 18.803135 | E8: =K_DFIG*WTG!$C$16/1000 -> 9.0367868 | F8: =K_IBR*BESS_Feeders!$C$10/1000 -> 2.1138683 | G8: =D8+E8+F8 -> 29.95379 | H8: =IF(G8<=40,"≤ 40 kA","EXCEEDS") -> ≤ 40 kA
A9: 4000 | B9: 0.1 | C9: =S_GSU/A9 -> 0.03125 | D9: =GSU_Sizing!$C$8/(C9+B9)/1000 -> 15.937896 | E9: =K_DFIG*WTG!$C$16/1000 -> 9.0367868 | F9: =K_IBR*BESS_Feeders!$C$10/1000 -> 2.1138683 | G9: =D9+E9+F9 -> 27.088551 | H9: =IF(G9<=40,"≤ 40 kA","EXCEEDS") -> ≤ 40 kA
A10: 4000 | B10: 0.12 | C10: =S_GSU/A10 -> 0.03125 | D10: =GSU_Sizing!$C$8/(C10+B10)/1000 -> 13.830405 | E10: =K_DFIG*WTG!$C$16/1000 -> 9.0367868 | F10: =K_IBR*BESS_Feeders!$C$10/1000 -> 2.1138683 | G10: =D10+E10+F10 -> 24.98106 | H10: =IF(G10<=40,"≤ 40 kA","EXCEEDS") -> ≤ 40 kA
A11: 8000 | B11: 0.08 | C11: =S_GSU/A11 -> 0.015625 | D11: =GSU_Sizing!$C$8/(C11+B11)/1000 -> 21.875543 | E11: =K_DFIG*WTG!$C$16/1000 -> 9.0367868 | F11: =K_IBR*BESS_Feeders!$C$10/1000 -> 2.1138683 | G11: =D11+E11+F11 -> 33.026198 | H11: =IF(G11<=40,"≤ 40 kA","EXCEEDS") -> ≤ 40 kA
A12: 8000 | B12: 0.1 | C12: =S_GSU/A12 -> 0.015625 | D12: =GSU_Sizing!$C$8/(C12+B12)/1000 -> 18.091665 | E12: =K_DFIG*WTG!$C$16/1000 -> 9.0367868 | F12: =K_IBR*BESS_Feeders!$C$10/1000 -> 2.1138683 | G12: =D12+E12+F12 -> 29.24232 | H12: =IF(G12<=40,"≤ 40 kA","EXCEEDS") -> ≤ 40 kA
A13: 8000 | B13: 0.12 | C13: =S_GSU/A13 -> 0.015625 | D13: =GSU_Sizing!$C$8/(C13+B13)/1000 -> 15.42377 | E13: =K_DFIG*WTG!$C$16/1000 -> 9.0367868 | F13: =K_IBR*BESS_Feeders!$C$10/1000 -> 2.1138683 | G13: =D13+E13+F13 -> 26.574425 | H13: =IF(G13<=40,"≤ 40 kA","EXCEEDS") -> ≤ 40 kA
A14: 1000000000 | B14: 0.08 | C14: =S_GSU/A14 -> 1.25e-07 | D14: =GSU_Sizing!$C$8/(C14+B14)/1000 -> 26.148069 | E14: =K_DFIG*WTG!$C$16/1000 -> 9.0367868 | F14: =K_IBR*BESS_Feeders!$C$10/1000 -> 2.1138683 | G14: =D14+E14+F14 -> 37.298724 | H14: =IF(G14<=40,"≤ 40 kA","EXCEEDS") -> ≤ 40 kA
A15: 1000000000 | B15: 0.1 | C15: =S_GSU/A15 -> 1.25e-07 | D15: =GSU_Sizing!$C$8/(C15+B15)/1000 -> 20.918462 | E15: =K_DFIG*WTG!$C$16/1000 -> 9.0367868 | F15: =K_IBR*BESS_Feeders!$C$10/1000 -> 2.1138683 | G15: =D15+E15+F15 -> 32.069117 | H15: =IF(G15<=40,"≤ 40 kA","EXCEEDS") -> ≤ 40 kA
A16: 1000000000 | B16: 0.12 | C16: =S_GSU/A16 -> 1.25e-07 | D16: =GSU_Sizing!$C$8/(C16+B16)/1000 -> 17.432055 | E16: =K_DFIG*WTG!$C$16/1000 -> 9.0367868 | F16: =K_IBR*BESS_Feeders!$C$10/1000 -> 2.1138683 | G16: =D16+E16+F16 -> 28.58271 | H16: =IF(G16<=40,"≤ 40 kA","EXCEEDS") -> ≤ 40 kA
A18: S_sc = 1E9 represents an infinite source (upper bound). Generator contributions are bounding arithmetic sums at the bus, ignoring WTG transformer/cable impedance — conservative.
A19: Asymmetry (X/R) and peak/closing duty must be checked per IEEE C37.010 once GSU X/R is known — GSU X/R can exceed the C37.04 standard X/R of 17.

Sheet Ratings
A1: Preliminary equipment rating basis (selected values are PRELIMINARY)
A2: PRELIMINARY ENGINEERING — NOT FOR CONSTRUCTION | Rev P0 | 2026-10-13
A4: Item | B4: Required / calculated | C4: Value | D4: Preliminary selection | E4: Status
A5: 34.5 kV main breaker continuous (A) | B5: GSU MV current at 125 MVA, V_MIN | C5: =GSU_Sizing!C9 -> 2201.9461 | D5: 3000 A | E5: Preliminary
A6: 34.5 kV wind feeder breaker (A) | B6: Max feeder I @V_MIN | C6: =MAX(Feeder_Sections!H12,Feeder_Sections!H38) -> 493.23593 | D6: 1200 A | E6: Preliminary
A7: 34.5 kV BESS feeder breaker (A) | B7: Per-feeder I @V_MIN (screening) | C7: =BESS_Feeders!C9 -> 463.5676 | D7: 1200 A | E7: Confirm with BESS design
A8: 34.5 kV bus (A) | B8: Max of (Σ wind @V_MIN, Σ BESS @V_MIN, GSU) | C8: =MAX(SUM(Feeder_Sections!H12,Feeder_Sections!H21,Feeder_Sections!H30,Feeder_Sections!H38),BESS_Feeders!C10/V_MIN,GSU_Sizing!C9) -> 2201.9461 | D8: 3000 A | E8: Preliminary
A9: 34.5 kV interrupting (kA sym) | B9: Max of screening cases | C9: =MAX(Fault_Screening!G5:G16) -> 37.298724 | D9: 40 kA (38 kV class, 150 kV BIL) | E9: Confirm by SC study
A10: 34.5 kV peak withstand (kA) | B10: 2.6 × I_sc (60 Hz, C37.04) | C10: =2.6*40 -> 104 | D10: 104 kA | E10: Preliminary
A11: 115 kV breaker continuous (A) | B11: GSU HV rated current | C11: =GSU_Sizing!C7 -> 627.55464 | D11: 1200 A min. (utility std. may be 2000 A) | E11: U
A12: 115 kV breaker interrupting | B12: Utility POI fault level + growth margin | C12: n/a | D12: TBD (40 or 63 kA class) | E12: OPEN — utility data
A13: 115 kV arrester MCOV (kV) | B13: ≥ 1.05 × 123/√3 | C13: =1.05*123/SQRT(3) -> 74.564787 | D13: ≥ 76 kV MCOV (96 kV duty-cycle) — confirm TOV | E13: Preliminary
A14: 34.5 kV arrester MCOV (kV), effectively grounded | B14: ≥ 1.05 × 36.2/√3 | C14: =1.05*36.2/SQRT(3) -> 21.945084 | D14: 22 kV MCOV min. if always effectively grounded; ≥ 36.5 kV MCOV (or TOV-curve justification) if islanded/ungrounded operation possible | E14: Open — grounding study
A15: 115 kV BIL | B15: IEEE C57.12.00 / C37.06 class | C15: n/a | D15: 550 kV (450 kV reduced only if insulation coordination permits) | E15: Preliminary
A16: 34.5 kV transformer winding BIL | B16: IEEE C57.12.00 | C16: n/a | D16: 200 kV | E16: Preliminary

Sheet POI_Scenarios
A1: POI operating scenarios — net flow vs internal loading (screening losses & aux)
A2: PRELIMINARY ENGINEERING — NOT FOR CONSTRUCTION | Rev P0 | 2026-10-13
A4: Scenario | B4: Wind at WTGs (MW) | C4: BESS at MV (+dis/−chg) (MW) | D4: Wind at POI (MW) | E4: BESS at POI (MW) | F4: Aux (MW) | G4: Net POI (MW, +export) | H4: Within ±100 MW? | I4: Wind feeder ΣI (A) | J4: BESS feeder ΣI (A) | K4: PPC action
A5: S1 Wind full, BESS idle | B5: 102.6 | C5: 0 | D5: =B5*(1-LOSS_W) -> 99.522 | E5: =IF(C5>0,C5*(1-LOSS_B),C5*(1+LOSS_B)) -> 0 | F5: =AUX -> 1 | G5: =D5+E5-F5 -> 98.522 | H5: =IF(AND(G5<=P_EXP,G5>=-P_IMP),"YES","NO — PPC limit") -> YES | I5: =B5/(N_WTG*P_WTG)*WTG!$C$16 -> 1807.3574 | J5: =ABS(C5)/P_BESS*BESS_Feeders!$C$10 -> 0 | K5: None — losses keep POI < 100 MW; PPC export limiter armed
A6: S2 Wind full, BESS charging 100 MW | B6: 102.6 | C6: -100 | D6: =B6*(1-LOSS_W) -> 99.522 | E6: =IF(C6>0,C6*(1-LOSS_B),C6*(1+LOSS_B)) -> -101.5 | F6: =AUX -> 1 | G6: =D6+E6-F6 -> -2.978 | H6: =IF(AND(G6<=P_EXP,G6>=-P_IMP),"YES","NO — PPC limit") -> YES | I6: =B6/(N_WTG*P_WTG)*WTG!$C$16 -> 1807.3574 | J6: =ABS(C6)/P_BESS*BESS_Feeders!$C$10 -> 1761.5569 | K6: POI ≈ 0 but ALL feeders fully loaded
A7: S3 No wind, BESS discharging 100 MW | B7: 0 | C7: 100 | D7: =B7*(1-LOSS_W) -> 0 | E7: =IF(C7>0,C7*(1-LOSS_B),C7*(1+LOSS_B)) -> 98.5 | F7: =AUX -> 1 | G7: =D7+E7-F7 -> 97.5 | H7: =IF(AND(G7<=P_EXP,G7>=-P_IMP),"YES","NO — PPC limit") -> YES | I7: =B7/(N_WTG*P_WTG)*WTG!$C$16 -> 0 | J7: =ABS(C7)/P_BESS*BESS_Feeders!$C$10 -> 1761.5569 | K7: None
A8: S4 Wind 60 MW + BESS 100 MW requested | B8: 60 | C8: 100 | D8: =B8*(1-LOSS_W) -> 58.2 | E8: =IF(C8>0,C8*(1-LOSS_B),C8*(1+LOSS_B)) -> 98.5 | F8: =AUX -> 1 | G8: =D8+E8-F8 -> 155.7 | H8: =IF(AND(G8<=P_EXP,G8>=-P_IMP),"YES","NO — PPC limit") -> NO — PPC limit | I8: =B8/(N_WTG*P_WTG)*WTG!$C$16 -> 1056.9341 | J8: =ABS(C8)/P_BESS*BESS_Feeders!$C$10 -> 1761.5569 | K8: PPC must curtail BESS (or wind) to hold ≤ 100 MW
A9: S5 No wind, BESS charging 100 MW requested | B9: 0 | C9: -100 | D9: =B9*(1-LOSS_W) -> 0 | E9: =IF(C9>0,C9*(1-LOSS_B),C9*(1+LOSS_B)) -> -101.5 | F9: =AUX -> 1 | G9: =D9+E9-F9 -> -102.5 | H9: =IF(AND(G9<=P_EXP,G9>=-P_IMP),"YES","NO — PPC limit") -> NO — PPC limit | I9: =B9/(N_WTG*P_WTG)*WTG!$C$16 -> 0 | J9: =ABS(C9)/P_BESS*BESS_Feeders!$C$10 -> 1761.5569 | K9: PPC must reduce charge so import (incl. aux & losses) ≤ 100 MW
A10: S6 Wind full + BESS discharge 20 MW requested | B10: 102.6 | C10: 20 | D10: =B10*(1-LOSS_W) -> 99.522 | E10: =IF(C10>0,C10*(1-LOSS_B),C10*(1+LOSS_B)) -> 19.7 | F10: =AUX -> 1 | G10: =D10+E10-F10 -> 118.222 | H10: =IF(AND(G10<=P_EXP,G10>=-P_IMP),"YES","NO — PPC limit") -> NO — PPC limit | I10: =B10/(N_WTG*P_WTG)*WTG!$C$16 -> 1807.3574 | J10: =ABS(C10)/P_BESS*BESS_Feeders!$C$10 -> 352.31138 | K10: PPC must hold BESS to ≈ 0–1.5 MW (or curtail wind)
A12: Feeder currents are set by each resource's own output; they are NOT reduced when wind export and BESS charging cancel at the POI (S2).
A13: Max BESS charge with no wind while respecting import limit (MW at PCS): | G13: =(P_IMP-AUX)/(1+LOSS_B) -> 97.536946

Sheet Check
A1: Independent check — workbook formulas vs Python engine (calc.py)
A2: PRELIMINARY ENGINEERING — NOT FOR CONSTRUCTION | Rev P0 | 2026-10-13
A4: Quantity | B4: Workbook | C4: Python | D4: Δ % | E4: Result
A5: WTG S (MVA) | B5: =WTG!C5 -> 4 | C5: 4 | D5: =IF(C5=0,0,(B5-C5)/C5) -> 0 | E5: =IF(ABS(D5)<0.005,"PASS","CHECK") -> PASS
A6: WTG I 690 V (A) | B6: =WTG!C8 -> 3346.9581 | C6: 3346.9581 | D6: =IF(C6=0,0,(B6-C6)/C6) -> 7.7294159e-11 | E6: =IF(ABS(D6)<0.005,"PASS","CHECK") -> PASS
A7: WTG I 34.5 kV (A) | B7: =WTG!C11 -> 66.939162 | C7: 66.939162 | D7: =IF(C7=0,0,(B7-C7)/C7) -> -5.3007234e-09 | E7: =IF(ABS(D7)<0.005,"PASS","CHECK") -> PASS
A8: WF-01 home-run I @1.0 pu (A) | B8: =Feeder_Sections!G12 -> 468.57413 | C8: 468.57413 | D8: =IF(C8=0,0,(B8-C8)/C8) -> -1.0324555e-09 | E8: =IF(ABS(D8)<0.005,"PASS","CHECK") -> PASS
A9: WF-04 home-run I @1.0 pu (A) | B9: =Feeder_Sections!G38 -> 401.63497 | C9: 401.63497 | D9: =IF(C9=0,0,(B9-C9)/C9) -> -3.2107749e-10 | E9: =IF(ABS(D9)<0.005,"PASS","CHECK") -> PASS
A10: Ampacity 1/0 (A) | B10: =Cable_Ampacity!Z5 -> 174.01904 | C10: 174.01904 | D10: =IF(C10=0,0,(B10-C10)/C10) -> -1.2973859e-09 | E10: =IF(ABS(D10)<0.005,"PASS","CHECK") -> PASS
A11: Ampacity 500 kcmil (A) | B11: =Cable_Ampacity!Z8 -> 400.71111 | C11: 400.71111 | D11: =IF(C11=0,0,(B11-C11)/C11) -> -1.0487846e-09 | E11: =IF(ABS(D11)<0.005,"PASS","CHECK") -> PASS
A12: Ampacity 1000 kcmil (A) | B12: =Cable_Ampacity!Z10 -> 572.04817 | C12: 572.04817 | D12: =IF(C12=0,0,(B12-C12)/C12) -> 7.426325e-10 | E12: =IF(ABS(D12)<0.005,"PASS","CHECK") -> PASS
A13: Rac 750 kcmil (Ω/km) | B13: =Cable_Ampacity!AC9 -> 0.099043149 | C13: 0.099043 | D13: =IF(C13=0,0,(B13-C13)/C13) -> 1.5060002e-06 | E13: =IF(ABS(D13)<0.005,"PASS","CHECK") -> PASS
A14: X 750 kcmil (Ω/km) | B14: =Cable_Ampacity!AD9 -> 0.13769322 | C14: 0.137693 | D14: =IF(C14=0,0,(B14-C14)/C14) -> 1.590336e-06 | E14: =IF(ABS(D14)<0.005,"PASS","CHECK") -> PASS
A15: Qc 1000 kcmil (kvar/km) | B15: =Cable_Ampacity!AB10 -> 110.36515 | C15: 110.36515 | D15: =IF(C15=0,0,(B15-C15)/C15) -> -2.2519423e-09 | E15: =IF(ABS(D15)<0.005,"PASS","CHECK") -> PASS
A16: BESS feeder I (A) | B16: =BESS_Feeders!C8 -> 440.38922 | C16: 440.38922 | D16: =IF(C16=0,0,(B16-C16)/C16) -> 7.9436337e-10 | E16: =IF(ABS(D16)<0.005,"PASS","CHECK") -> PASS
A17: GSU HV rated I (A) | B17: =GSU_Sizing!C7 -> 627.55464 | C17: 627.55464 | D17: =IF(C17=0,0,(B17-C17)/C17) -> 6.7485171e-10 | E17: =IF(ABS(D17)<0.005,"PASS","CHECK") -> PASS
A18: GSU MV rated I (A) | B18: =GSU_Sizing!C8 -> 2091.8488 | C18: 2091.8488 | D18: =IF(C18=0,0,(B18-C18)/C18) -> 1.9680571e-10 | E18: =IF(ABS(D18)<0.005,"PASS","CHECK") -> PASS
A19: GSU max equiv MVA | B19: =GSU_Sizing!F23 -> 110.80332 | C19: 110.80332 | D19: =IF(C19=0,0,(B19-C19)/C19) -> 9.0000004e-10 | E19: =IF(ABS(D19)<0.005,"PASS","CHECK") -> PASS
A20: Q required at HV (Mvar) | B20: =GSU_Sizing!C5 -> 32.868411 | C20: 32.868411 | D20: =IF(C20=0,0,(B20-C20)/C20) -> -1.4667995e-08 | E20: =IF(ABS(D20)<0.005,"PASS","CHECK") -> PASS
A21: Fault, ∞ bus, Z=0.10 total (kA) | B21: =Fault_Screening!G15 -> 32.069117 | C21: 32.069143 | D21: =IF(C21=0,0,(B21-C21)/C21) -> -8.1228809e-07 | E21: =IF(ABS(D21)<0.005,"PASS","CHECK") -> PASS
A22: 500 kcmil 0.5 s withstand (kA) | B22: =SC_Withstand!E11 -> 33.266479 | C22: 33.266479 | D22: =IF(C22=0,0,(B22-C22)/C22) -> -7.97668e-09 | E22: =IF(ABS(D22)<0.005,"PASS","CHECK") -> PASS
A23: WF-01 ΣΔV @ illustrative 5 km (%) | B23: =Feeder_Sections!O12*100 -> 2.5728369 | C23: 2.572837 | D23: =IF(C23=0,0,(B23-C23)/C23) -> -2.2273668e-08 | E23: =IF(ABS(D23)<0.005,"PASS","CHECK") -> PASS
